Workbook

Sheet Braki_z kodami
C1: Dzienny rejestr braków - inspekcja | U1: Numer: F.QA.04.01.02 | AH1: A | AI1: PW Plus | AJ1: Prasy
U2: Wydanie: 06 | AH2: B | AI2: ZP Pon | AJ2: Wtryskarki
U3: Strona 1 z 1 | AH3: C | AJ3: PHE
AJ4: ICL
B5: ZP Pon | G5: Data sprwdz | H5: =TODAY() -> 46150 | S5: PHE
A7: C | B7: Nr wewn. zlec. Prod | C7: Item | D7: Data Produkcji | E7: Operator na kontroli | F7: Sprawdzono | G7: Ilość braków | H7: Braki (z podziałem na kody) | AE7: Uwagi
H8: A | I8: B | J8: C | K8: D | L8: E | M8: F | N8: G | O8: H | P8: I | Q8: J | R8: K | S8: L | T8: M | U8: N | V8: O | W8: P | X8: R | Y8: S | Z8: T | AA8: U | AB8: V | AC8: W | AD8: X
E9: 025/P | G9: =SUM(H9:AD9) -> 0 | AI9: =CONCATENATE(IF(I9="","",$I$8),I9) | AJ9: =CONCATENATE(IF(J9="","",$J$8),J9) | AK9: =CONCATENATE(IF(K9="","",$K$8),K9) | AL9: =CONCATENATE(IF(L9="","",$L$8),L9) | AM9: =CONCATENATE(IF(M9="","",$M$8),M9) | AN9: =CONCATENATE(IF(N9="","",$N$8),N9) | AO9: =CONCATENATE(IF(R9="","",$R$8),R9) | AP9: =CONCATENATE(IF(S9="","",$S$8),S9) | AQ9: =CONCATENATE(IF(T9="","",$T$8),T9) | AR9: =CONCATENATE(IF(U9="","",$U$8),U9) | AS9: =CONCATENATE(IF(V9="","",$V$8),V9) | AT9: =CONCATENATE(IF(W9="","",$W$8),W9) | AU9: =CONCATENATE(IF(X9="","",$X$8),X9) | AV9: =CONCATENATE(IF(Y9="","",$Y$8),Y9) | AW9: =CONCATENATE(IF(Z9="","",$Z$8),Z9) | AX9: =CONCATENATE(IF(AA9="","",$AA$8),AA9) | AY9: =CONCATENATE(IF(AB9="","",AB$8),AB9) | AZ9: =CONCATENATE(IF(AC9="","",AC$8),AC9) | BA9: =CONCATENATE(IF(AD9="","",$AD$8),AD9) | BB9: =AND(BC9,BD9,BE9,BF9,BG9,BH9,BI9,BJ9,BK9,BL9,BM9,BN9,BO9,BP9,BQ9,BR9,BS9,BT9,BU9,BV9,BW9,BX9,BY9,BZ9,CA9) -> TRUE | BC9: =ISERROR(SEARCH("`",B9)) -> TRUE | BD9: =ISERROR(SEARCH("<",B9)) -> TRUE | BE9: =ISERROR(SEARCH(">",B9)) -> TRUE | BF9: =ISERROR(SEARCH(":",B9)) -> TRUE | BG9: =ISERROR(SEARCH(",",B9)) -> TRUE | BH9: =ISERROR(SEARCH(";",B9)) -> TRUE | BI9: =ISERROR(SEARCH("|",B9)) -> TRUE | BJ9: =ISERROR(SEARCH("\",B9)) -> TRUE | BK9: =ISERROR(SEARCH("[",B9)) -> TRUE | BL9: =ISERROR(SEARCH("]",B9)) -> TRUE | BM9: =ISERROR(SEARCH("{",B9)) -> TRUE | BN9: =ISERROR(SEARCH("}",B9)) -> TRUE | BO9: =ISERROR(SEARCH("_",B9)) -> TRUE | BP9: =ISERROR(SEARCH("(",B9)) -> TRUE | BQ9: =ISERROR(SEARCH(")",B9)) -> TRUE | BR9: =ISERROR(SEARCH("&",B9)) -> TRUE | BS9: =ISERROR(SEARCH("^",B9)) -> TRUE | BT9: =ISERROR(SEARCH("#",B9)) -> TRUE | BU9: =ISERROR(SEARCH("@",B9)) -> TRUE | BV9: =ISERROR(SEARCH("!",B9)) -> TRUE | BW9: =ISERROR(SEARCH("~?",B9)) -> TRUE | BX9: =ISERROR(SEARCH("~*",B9)) -> TRUE | BY9: =ISERROR(SEARCH("=",B9)) -> TRUE | BZ9: =ISERROR(SEARCH("""",B9)) -> TRUE | CA9: =ISERROR(SEARCH(" ",B9)) -> TRUE
A10: =CONCATENATE("*",B9,"$",D9-(DATE(YEAR(D9),1,1)-1),A9,F9,AH9,AI9,AJ9,AK9,AL9,AM9,AN9,AO9,AP9,AQ9,AR9,AS9,AT9,AU9,AV9,AW9,AX9,AY9,AZ9,BA9,"*") -> *$0* | S10: =CONCATENATE("*",C9,"*") -> ** | BB10: =AND(BC10,BD10,BE10,BF10,BG10,BH10,BI10,BJ10,BK10,BL10,BM10,BN10,BO10,BP10,BQ10,BR10,BS10,BT10,BU10,BV10,BW10,BX10,BY10,BZ10,CA10) -> TRUE | BC10: =ISERROR(SEARCH("`",D9)) -> TRUE | BD10: =ISERROR(SEARCH("<",D9)) -> TRUE | BE10: =ISERROR(SEARCH(">",D9)) -> TRUE | BF10: =ISERROR(SEARCH(":",D9)) -> TRUE | BG10: =ISERROR(SEARCH(",",D9)) -> TRUE | BH10: =ISERROR(SEARCH(";",D9)) -> TRUE | BI10: =ISERROR(SEARCH("|",D9)) -> TRUE | BJ10: =ISERROR(SEARCH("\",D9)) -> TRUE | BK10: =ISERROR(SEARCH("[",D9)) -> TRUE | BL10: =ISERROR(SEARCH("]",D9)) -> TRUE | BM10: =ISERROR(SEARCH("{",D9)) -> TRUE | BN10: =ISERROR(SEARCH("}",D9)) -> TRUE | BO10: =ISERROR(SEARCH("_",D9)) -> TRUE | BP10: =ISERROR(SEARCH("(",D9)) -> TRUE | BQ10: =ISERROR(SEARCH(")",D9)) -> TRUE | BR10: =ISERROR(SEARCH("&",D9)) -> TRUE | BS10: =ISERROR(SEARCH("^",D9)) -> TRUE | BT10: =ISERROR(SEARCH("#",D9)) -> TRUE | BU10: =ISERROR(SEARCH("@",D9)) -> TRUE | BV10: =ISERROR(SEARCH("!",D9)) -> TRUE | BW10: =ISERROR(SEARCH("~?",D9)) -> TRUE | BX10: =ISERROR(SEARCH("~*",D9)) -> TRUE | BY10: =ISERROR(SEARCH("=",D9)) -> TRUE | BZ10: =ISERROR(SEARCH("""",D9)) -> TRUE | CA10: =ISERROR(SEARCH(" ",D9)) -> TRUE
E11: 025/P | G11: =SUM(H11:AD11) -> 0 | AI11: =CONCATENATE(IF(I11="","",$I$8),I11) | AJ11: =CONCATENATE(IF(J11="","",$J$8),J11) | AK11: =CONCATENATE(IF(K11="","",$K$8),K11) | AL11: =CONCATENATE(IF(L11="","",$L$8),L11) | AM11: =CONCATENATE(IF(M11="","",$M$8),M11) | AN11: =CONCATENATE(IF(N11="","",$N$8),N11) | AO11: =CONCATENATE(IF(R11="","",$R$8),R11) | AP11: =CONCATENATE(IF(S11="","",$S$8),S11) | AQ11: =CONCATENATE(IF(T11="","",$T$8),T11) | AR11: =CONCATENATE(IF(U11="","",$U$8),U11) | AS11: =CONCATENATE(IF(V11="","",$V$8),V11) | AT11: =CONCATENATE(IF(W11="","",$W$8),W11) | AU11: =CONCATENATE(IF(X11="","",$X$8),X11) | AV11: =CONCATENATE(IF(Y11="","",$Y$8),Y11) | AW11: =CONCATENATE(IF(Z11="","",$Z$8),Z11) | AX11: =CONCATENATE(IF(AA11="","",$AA$8),AA11) | AY11: =CONCATENATE(IF(AB11="","",AB$8),AB11) | AZ11: =CONCATENATE(IF(AC11="","",AC$8),AC11) | BA11: =CONCATENATE(IF(AD11="","",$AD$8),AD11) | BB11: =AND(BC11,BD11,BE11,BF11,BG11,BH11,BI11,BJ11,BK11,BL11,BM11,BN11,BO11,BP11,BQ11,BR11,BS11,BT11,BU11,BV11,BW11,BX11,BY11,BZ11,CA11) -> TRUE | BC11: =ISERROR(SEARCH("`",B11)) -> TRUE | BD11: =ISERROR(SEARCH("<",B11)) -> TRUE | BE11: =ISERROR(SEARCH(">",B11)) -> TRUE | BF11: =ISERROR(SEARCH(":",B11)) -> TRUE | BG11: =ISERROR(SEARCH(",",B11)) -> TRUE | BH11: =ISERROR(SEARCH(";",B11)) -> TRUE | BI11: =ISERROR(SEARCH("|",B11)) -> TRUE | BJ11: =ISERROR(SEARCH("\",B11)) -> TRUE | BK11: =ISERROR(SEARCH("[",B11)) -> TRUE | BL11: =ISERROR(SEARCH("]",B11)) -> TRUE | BM11: =ISERROR(SEARCH("{",B11)) -> TRUE | BN11: =ISERROR(SEARCH("}",B11)) -> TRUE | BO11: =ISERROR(SEARCH("_",B11)) -> TRUE | BP11: =ISERROR(SEARCH("(",B11)) -> TRUE | BQ11: =ISERROR(SEARCH(")",B11)) -> TRUE | BR11: =ISERROR(SEARCH("&",B11)) -> TRUE | BS11: =ISERROR(SEARCH("^",B11)) -> TRUE | BT11: =ISERROR(SEARCH("#",B11)) -> TRUE | BU11: =ISERROR(SEARCH("@",B11)) -> TRUE | BV11: =ISERROR(SEARCH("!",B11)) -> TRUE | BW11: =ISERROR(SEARCH("~?",B11)) -> TRUE | BX11: =ISERROR(SEARCH("~*",B11)) -> TRUE | BY11: =ISERROR(SEARCH("=",B11)) -> TRUE | BZ11: =ISERROR(SEARCH("""",B11)) -> TRUE | CA11: =ISERROR(SEARCH(" ",B11)) -> TRUE
A12: =CONCATENATE("*",B11,"$",D11-(DATE(YEAR(D11),1,1)-1),A11,F11,AH11,AI11,AJ11,AK11,AL11,AM11,AN11,AO11,AP11,AQ11,AR11,AS11,AT11,AU11,AV11,AW11,AX11,AY11,AZ11,BA11,"*") -> *$0* | S12: =CONCATENATE("*",C11,"*") -> ** | BB12: =AND(BC12,BD12,BE12,BF12,BG12,BH12,BI12,BJ12,BK12,BL12,BM12,BN12,BO12,BP12,BQ12,BR12,BS12,BT12,BU12,BV12,BW12,BX12,BY12,BZ12,CA12) -> TRUE | BC12: =ISERROR(SEARCH("`",D11)) -> TRUE | BD12: =ISERROR(SEARCH("<",D11)) -> TRUE | BE12: =ISERROR(SEARCH(">",D11)) -> TRUE | BF12: =ISERROR(SEARCH(":",D11)) -> TRUE | BG12: =ISERROR(SEARCH(",",D11)) -> TRUE | BH12: =ISERROR(SEARCH(";",D11)) -> TRUE | BI12: =ISERROR(SEARCH("|",D11)) -> TRUE | BJ12: =ISERROR(SEARCH("\",D11)) -> TRUE | BK12: =ISERROR(SEARCH("[",D11)) -> TRUE | BL12: =ISERROR(SEARCH("]",D11)) -> TRUE | BM12: =ISERROR(SEARCH("{",D11)) -> TRUE | BN12: =ISERROR(SEARCH("}",D11)) -> TRUE | BO12: =ISERROR(SEARCH("_",D11)) -> TRUE | BP12: =ISERROR(SEARCH("(",D11)) -> TRUE | BQ12: =ISERROR(SEARCH(")",D11)) -> TRUE | BR12: =ISERROR(SEARCH("&",D11)) -> TRUE | BS12: =ISERROR(SEARCH("^",D11)) -> TRUE | BT12: =ISERROR(SEARCH("#",D11)) -> TRUE | BU12: =ISERROR(SEARCH("@",D11)) -> TRUE | BV12: =ISERROR(SEARCH("!",D11)) -> TRUE | BW12: =ISERROR(SEARCH("~?",D11)) -> TRUE | BX12: =ISERROR(SEARCH("~*",D11)) -> TRUE | BY12: =ISERROR(SEARCH("=",D11)) -> TRUE | BZ12: =ISERROR(SEARCH("""",D11)) -> TRUE | CA12: =ISERROR(SEARCH(" ",D11)) -> TRUE
E13: 025/P | G13: =SUM(H13:AD13) -> 0 | AI13: =CONCATENATE(IF(I13="","",$I$8),I13) | AJ13: =CONCATENATE(IF(J13="","",$J$8),J13) | AK13: =CONCATENATE(IF(K13="","",$K$8),K13) | AL13: =CONCATENATE(IF(L13="","",$L$8),L13) | AM13: =CONCATENATE(IF(M13="","",$M$8),M13) | AN13: =CONCATENATE(IF(N13="","",$N$8),N13) | AO13: =CONCATENATE(IF(R13="","",$R$8),R13) | AP13: =CONCATENATE(IF(S13="","",$S$8),S13) | AQ13: =CONCATENATE(IF(T13="","",$T$8),T13) | AR13: =CONCATENATE(IF(U13="","",$U$8),U13) | AS13: =CONCATENATE(IF(V13="","",$V$8),V13) | AT13: =CONCATENATE(IF(W13="","",$W$8),W13) | AU13: =CONCATENATE(IF(X13="","",$X$8),X13) | AV13: =CONCATENATE(IF(Y13="","",$Y$8),Y13) | AW13: =CONCATENATE(IF(Z13="","",$Z$8),Z13) | AX13: =CONCATENATE(IF(AA13="","",$AA$8),AA13) | AY13: =CONCATENATE(IF(AB13="","",AB$8),AB13) | AZ13: =CONCATENATE(IF(AC13="","",AC$8),AC13) | BA13: =CONCATENATE(IF(AD13="","",$AD$8),AD13) | BB13: =AND(BC13,BD13,BE13,BF13,BG13,BH13,BI13,BJ13,BK13,BL13,BM13,BN13,BO13,BP13,BQ13,BR13,BS13,BT13,BU13,BV13,BW13,BX13,BY13,BZ13,CA13) -> TRUE | BC13: =ISERROR(SEARCH("`",B13)) -> TRUE | BD13: =ISERROR(SEARCH("<",B13)) -> TRUE | BE13: =ISERROR(SEARCH(">",B13)) -> TRUE | BF13: =ISERROR(SEARCH(":",B13)) -> TRUE | BG13: =ISERROR(SEARCH(",",B13)) -> TRUE | BH13: =ISERROR(SEARCH(";",B13)) -> TRUE | BI13: =ISERROR(SEARCH("|",B13)) -> TRUE | BJ13: =ISERROR(SEARCH("\",B13)) -> TRUE | BK13: =ISERROR(SEARCH("[",B13)) -> TRUE | BL13: =ISERROR(SEARCH("]",B13)) -> TRUE | BM13: =ISERROR(SEARCH("{",B13)) -> TRUE | BN13: =ISERROR(SEARCH("}",B13)) -> TRUE | BO13: =ISERROR(SEARCH("_",B13)) -> TRUE | BP13: =ISERROR(SEARCH("(",B13)) -> TRUE | BQ13: =ISERROR(SEARCH(")",B13)) -> TRUE | BR13: =ISERROR(SEARCH("&",B13)) -> TRUE | BS13: =ISERROR(SEARCH("^",B13)) -> TRUE | BT13: =ISERROR(SEARCH("#",B13)) -> TRUE | BU13: =ISERROR(SEARCH("@",B13)) -> TRUE | BV13: =ISERROR(SEARCH("!",B13)) -> TRUE | BW13: =ISERROR(SEARCH("~?",B13)) -> TRUE | BX13: =ISERROR(SEARCH("~*",B13)) -> TRUE | BY13: =ISERROR(SEARCH("=",B13)) -> TRUE | BZ13: =ISERROR(SEARCH("""",B13)) -> TRUE | CA13: =ISERROR(SEARCH(" ",B13)) -> TRUE
A14: =CONCATENATE("*",B13,"$",D13-(DATE(YEAR(D13),1,1)-1),A13,F13,AH13,AI13,AJ13,AK13,AL13,AM13,AN13,AO13,AP13,AQ13,AR13,AS13,AT13,AU13,AV13,AW13,AX13,AY13,AZ13,BA13,"*") -> *$0* | S14: =CONCATENATE("*",C13,"*") -> ** | BB14: =AND(BC14,BD14,BE14,BF14,BG14,BH14,BI14,BJ14,BK14,BL14,BM14,BN14,BO14,BP14,BQ14,BR14,BS14,BT14,BU14,BV14,BW14,BX14,BY14,BZ14,CA14) -> TRUE | BC14: =ISERROR(SEARCH("`",D13)) -> TRUE | BD14: =ISERROR(SEARCH("<",D13)) -> TRUE | BE14: =ISERROR(SEARCH(">",D13)) -> TRUE | BF14: =ISERROR(SEARCH(":",D13)) -> TRUE | BG14: =ISERROR(SEARCH(",",D13)) -> TRUE | BH14: =ISERROR(SEARCH(";",D13)) -> TRUE | BI14: =ISERROR(SEARCH("|",D13)) -> TRUE | BJ14: =ISERROR(SEARCH("\",D13)) -> TRUE | BK14: =ISERROR(SEARCH("[",D13)) -> TRUE | BL14: =ISERROR(SEARCH("]",D13)) -> TRUE | BM14: =ISERROR(SEARCH("{",D13)) -> TRUE | BN14: =ISERROR(SEARCH("}",D13)) -> TRUE | BO14: =ISERROR(SEARCH("_",D13)) -> TRUE | BP14: =ISERROR(SEARCH("(",D13)) -> TRUE | BQ14: =ISERROR(SEARCH(")",D13)) -> TRUE | BR14: =ISERROR(SEARCH("&",D13)) -> TRUE | BS14: =ISERROR(SEARCH("^",D13)) -> TRUE | BT14: =ISERROR(SEARCH("#",D13)) -> TRUE | BU14: =ISERROR(SEARCH("@",D13)) -> TRUE | BV14: =ISERROR(SEARCH("!",D13)) -> TRUE | BW14: =ISERROR(SEARCH("~?",D13)) -> TRUE | BX14: =ISERROR(SEARCH("~*",D13)) -> TRUE | BY14: =ISERROR(SEARCH("=",D13)) -> TRUE | BZ14: =ISERROR(SEARCH("""",D13)) -> TRUE | CA14: =ISERROR(SEARCH(" ",D13)) -> TRUE
E15: 025/P | G15: =SUM(H15:AD15) -> 0 | AI15: =CONCATENATE(IF(I15="","",$I$8),I15) | AJ15: =CONCATENATE(IF(J15="","",$J$8),J15) | AK15: =CONCATENATE(IF(K15="","",$K$8),K15) | AL15: =CONCATENATE(IF(L15="","",$L$8),L15) | AM15: =CONCATENATE(IF(M15="","",$M$8),M15) | AN15: =CONCATENATE(IF(N15="","",$N$8),N15) | AO15: =CONCATENATE(IF(R15="","",$R$8),R15) | AP15: =CONCATENATE(IF(S15="","",$S$8),S15) | AQ15: =CONCATENATE(IF(T15="","",$T$8),T15) | AR15: =CONCATENATE(IF(U15="","",$U$8),U15) | AS15: =CONCATENATE(IF(V15="","",$V$8),V15) | AT15: =CONCATENATE(IF(W15="","",$W$8),W15) | AU15: =CONCATENATE(IF(X15="","",$X$8),X15) | AV15: =CONCATENATE(IF(Y15="","",$Y$8),Y15) | AW15: =CONCATENATE(IF(Z15="","",$Z$8),Z15) | AX15: =CONCATENATE(IF(AA15="","",$AA$8),AA15) | AY15: =CONCATENATE(IF(AB15="","",AB$8),AB15) | AZ15: =CONCATENATE(IF(AC15="","",AC$8),AC15) | BA15: =CONCATENATE(IF(AD15="","",$AD$8),AD15) | BB15: =AND(BC15,BD15,BE15,BF15,BG15,BH15,BI15,BJ15,BK15,BL15,BM15,BN15,BO15,BP15,BQ15,BR15,BS15,BT15,BU15,BV15,BW15,BX15,BY15,BZ15,CA15) -> TRUE | BC15: =ISERROR(SEARCH("`",B15)) -> TRUE | BD15: =ISERROR(SEARCH("<",B15)) -> TRUE | BE15: =ISERROR(SEARCH(">",B15)) -> TRUE | BF15: =ISERROR(SEARCH(":",B15)) -> TRUE | BG15: =ISERROR(SEARCH(",",B15)) -> TRUE | BH15: =ISERROR(SEARCH(";",B15)) -> TRUE | BI15: =ISERROR(SEARCH("|",B15)) -> TRUE | BJ15: =ISERROR(SEARCH("\",B15)) -> TRUE | BK15: =ISERROR(SEARCH("[",B15)) -> TRUE | BL15: =ISERROR(SEARCH("]",B15)) -> TRUE | BM15: =ISERROR(SEARCH("{",B15)) -> TRUE | BN15: =ISERROR(SEARCH("}",B15)) -> TRUE | BO15: =ISERROR(SEARCH("_",B15)) -> TRUE | BP15: =ISERROR(SEARCH("(",B15)) -> TRUE | BQ15: =ISERROR(SEARCH(")",B15)) -> TRUE | BR15: =ISERROR(SEARCH("&",B15)) -> TRUE | BS15: =ISERROR(SEARCH("^",B15)) -> TRUE | BT15: =ISERROR(SEARCH("#",B15)) -> TRUE | BU15: =ISERROR(SEARCH("@",B15)) -> TRUE | BV15: =ISERROR(SEARCH("!",B15)) -> TRUE | BW15: =ISERROR(SEARCH("~?",B15)) -> TRUE | BX15: =ISERROR(SEARCH("~*",B15)) -> TRUE | BY15: =ISERROR(SEARCH("=",B15)) -> TRUE | BZ15: =ISERROR(SEARCH("""",B15)) -> TRUE | CA15: =ISERROR(SEARCH(" ",B15)) -> TRUE
A16: =CONCATENATE("*",B15,"$",D15-(DATE(YEAR(D15),1,1)-1),A15,F15,AH15,AI15,AJ15,AK15,AL15,AM15,AN15,AO15,AP15,AQ15,AR15,AS15,AT15,AU15,AV15,AW15,AX15,AY15,AZ15,BA15,"*") -> *$0* | S16: =CONCATENATE("*",C15,"*") -> ** | BB16: =AND(BC16,BD16,BE16,BF16,BG16,BH16,BI16,BJ16,BK16,BL16,BM16,BN16,BO16,BP16,BQ16,BR16,BS16,BT16,BU16,BV16,BW16,BX16,BY16,BZ16,CA16) -> TRUE | BC16: =ISERROR(SEARCH("`",D15)) -> TRUE | BD16: =ISERROR(SEARCH("<",D15)) -> TRUE | BE16: =ISERROR(SEARCH(">",D15)) -> TRUE | BF16: =ISERROR(SEARCH(":",D15)) -> TRUE | BG16: =ISERROR(SEARCH(",",D15)) -> TRUE | BH16: =ISERROR(SEARCH(";",D15)) -> TRUE | BI16: =ISERROR(SEARCH("|",D15)) -> TRUE | BJ16: =ISERROR(SEARCH("\",D15)) -> TRUE | BK16: =ISERROR(SEARCH("[",D15)) -> TRUE | BL16: =ISERROR(SEARCH("]",D15)) -> TRUE | BM16: =ISERROR(SEARCH("{",D15)) -> TRUE | BN16: =ISERROR(SEARCH("}",D15)) -> TRUE | BO16: =ISERROR(SEARCH("_",D15)) -> TRUE | BP16: =ISERROR(SEARCH("(",D15)) -> TRUE | BQ16: =ISERROR(SEARCH(")",D15)) -> TRUE | BR16: =ISERROR(SEARCH("&",D15)) -> TRUE | BS16: =ISERROR(SEARCH("^",D15)) -> TRUE | BT16: =ISERROR(SEARCH("#",D15)) -> TRUE | BU16: =ISERROR(SEARCH("@",D15)) -> TRUE | BV16: =ISERROR(SEARCH("!",D15)) -> TRUE | BW16: =ISERROR(SEARCH("~?",D15)) -> TRUE | BX16: =ISERROR(SEARCH("~*",D15)) -> TRUE | BY16: =ISERROR(SEARCH("=",D15)) -> TRUE | BZ16: =ISERROR(SEARCH("""",D15)) -> TRUE | CA16: =ISERROR(SEARCH(" ",D15)) -> TRUE
E17: 025/P | G17: =SUM(H17:AD17) -> 0 | AI17: =CONCATENATE(IF(I17="","",$I$8),I17) | AJ17: =CONCATENATE(IF(J17="","",$J$8),J17) | AK17: =CONCATENATE(IF(K17="","",$K$8),K17) | AL17: =CONCATENATE(IF(L17="","",$L$8),L17) | AM17: =CONCATENATE(IF(M17="","",$M$8),M17) | AN17: =CONCATENATE(IF(N17="","",$N$8),N17) | AO17: =CONCATENATE(IF(R17="","",$R$8),R17) | AP17: =CONCATENATE(IF(S17="","",$S$8),S17) | AQ17: =CONCATENATE(IF(T17="","",$T$8),T17) | AR17: =CONCATENATE(IF(U17="","",$U$8),U17) | AS17: =CONCATENATE(IF(V17="","",$V$8),V17) | AT17: =CONCATENATE(IF(W17="","",$W$8),W17) | AU17: =CONCATENATE(IF(X17="","",$X$8),X17) | AV17: =CONCATENATE(IF(Y17="","",$Y$8),Y17) | AW17: =CONCATENATE(IF(Z17="","",$Z$8),Z17) | AX17: =CONCATENATE(IF(AA17="","",$AA$8),AA17) | AY17: =CONCATENATE(IF(AB17="","",AB$8),AB17) | AZ17: =CONCATENATE(IF(AC17="","",AC$8),AC17) | BA17: =CONCATENATE(IF(AD17="","",$AD$8),AD17) | BB17: =AND(BC17,BD17,BE17,BF17,BG17,BH17,BI17,BJ17,BK17,BL17,BM17,BN17,BO17,BP17,BQ17,BR17,BS17,BT17,BU17,BV17,BW17,BX17,BY17,BZ17,CA17) -> TRUE | BC17: =ISERROR(SEARCH("`",B17)) -> TRUE | BD17: =ISERROR(SEARCH("<",B17)) -> TRUE | BE17: =ISERROR(SEARCH(">",B17)) -> TRUE | BF17: =ISERROR(SEARCH(":",B17)) -> TRUE | BG17: =ISERROR(SEARCH(",",B17)) -> TRUE | BH17: =ISERROR(SEARCH(";",B17)) -> TRUE | BI17: =ISERROR(SEARCH("|",B17)) -> TRUE | BJ17: =ISERROR(SEARCH("\",B17)) -> TRUE | BK17: =ISERROR(SEARCH("[",B17)) -> TRUE | BL17: =ISERROR(SEARCH("]",B17)) -> TRUE | BM17: =ISERROR(SEARCH("{",B17)) -> TRUE | BN17: =ISERROR(SEARCH("}",B17)) -> TRUE | BO17: =ISERROR(SEARCH("_",B17)) -> TRUE | BP17: =ISERROR(SEARCH("(",B17)) -> TRUE | BQ17: =ISERROR(SEARCH(")",B17)) -> TRUE | BR17: =ISERROR(SEARCH("&",B17)) -> TRUE | BS17: =ISERROR(SEARCH("^",B17)) -> TRUE | BT17: =ISERROR(SEARCH("#",B17)) -> TRUE | BU17: =ISERROR(SEARCH("@",B17)) -> TRUE | BV17: =ISERROR(SEARCH("!",B17)) -> TRUE | BW17: =ISERROR(SEARCH("~?",B17)) -> TRUE | BX17: =ISERROR(SEARCH("~*",B17)) -> TRUE | BY17: =ISERROR(SEARCH("=",B17)) -> TRUE | BZ17: =ISERROR(SEARCH("""",B17)) -> TRUE | CA17: =ISERROR(SEARCH(" ",B17)) -> TRUE
A18: =CONCATENATE("*",B17,"$",D17-(DATE(YEAR(D17),1,1)-1),A17,F17,AH17,AI17,AJ17,AK17,AL17,AM17,AN17,AO17,AP17,AQ17,AR17,AS17,AT17,AU17,AV17,AW17,AX17,AY17,AZ17,BA17,"*") -> *$0* | S18: =CONCATENATE("*",C17,"*") -> ** | BB18: =AND(BC18,BD18,BE18,BF18,BG18,BH18,BI18,BJ18,BK18,BL18,BM18,BN18,BO18,BP18,BQ18,BR18,BS18,BT18,BU18,BV18,BW18,BX18,BY18,BZ18,CA18) -> TRUE | BC18: =ISERROR(SEARCH("`",D17)) -> TRUE | BD18: =ISERROR(SEARCH("<",D17)) -> TRUE | BE18: =ISERROR(SEARCH(">",D17)) -> TRUE | BF18: =ISERROR(SEARCH(":",D17)) -> TRUE | BG18: =ISERROR(SEARCH(",",D17)) -> TRUE | BH18: =ISERROR(SEARCH(";",D17)) -> TRUE | BI18: =ISERROR(SEARCH("|",D17)) -> TRUE | BJ18: =ISERROR(SEARCH("\",D17)) -> TRUE | BK18: =ISERROR(SEARCH("[",D17)) -> TRUE | BL18: =ISERROR(SEARCH("]",D17)) -> TRUE | BM18: =ISERROR(SEARCH("{",D17)) -> TRUE | BN18: =ISERROR(SEARCH("}",D17)) -> TRUE | BO18: =ISERROR(SEARCH("_",D17)) -> TRUE | BP18: =ISERROR(SEARCH("(",D17)) -> TRUE | BQ18: =ISERROR(SEARCH(")",D17)) -> TRUE | BR18: =ISERROR(SEARCH("&",D17)) -> TRUE | BS18: =ISERROR(SEARCH("^",D17)) -> TRUE | BT18: =ISERROR(SEARCH("#",D17)) -> TRUE | BU18: =ISERROR(SEARCH("@",D17)) -> TRUE | BV18: =ISERROR(SEARCH("!",D17)) -> TRUE | BW18: =ISERROR(SEARCH("~?",D17)) -> TRUE | BX18: =ISERROR(SEARCH("~*",D17)) -> TRUE | BY18: =ISERROR(SEARCH("=",D17)) -> TRUE | BZ18: =ISERROR(SEARCH("""",D17)) -> TRUE | CA18: =ISERROR(SEARCH(" ",D17)) -> TRUE
E19: 025/P | G19: =SUM(H19:AD19) -> 0
A20: =CONCATENATE("*",B19,"$",D19-(DATE(YEAR(D19),1,1)-1),A19,F19,AH19,AI19,AJ19,AK19,AL19,AM19,AN19,AO19,AP19,AQ19,AR19,AS19,AT19,AU19,AV19,AW19,AX19,AY19,AZ19,BA19,"*") -> *$0* | S20: =CONCATENATE("*",C19,"*") -> **
E21: 025/P | G21: =SUM(H21:AD21) -> 0 | AI21: =CONCATENATE(IF(I21="","",$I$8),I21) | AJ21: =CONCATENATE(IF(J21="","",$J$8),J21) | AK21: =CONCATENATE(IF(K21="","",$K$8),K21) | AL21: =CONCATENATE(IF(L21="","",$L$8),L21) | AM21: =CONCATENATE(IF(M21="","",$M$8),M21) | AN21: =CONCATENATE(IF(N21="","",$N$8),N21) | AO21: =CONCATENATE(IF(R21="","",$R$8),R21) | AP21: =CONCATENATE(IF(S21="","",$S$8),S21) | AQ21: =CONCATENATE(IF(T21="","",$T$8),T21) | AR21: =CONCATENATE(IF(U21="","",$U$8),U21) | AS21: =CONCATENATE(IF(V21="","",$V$8),V21) | AT21: =CONCATENATE(IF(W21="","",$W$8),W21) | AU21: =CONCATENATE(IF(X21="","",$X$8),X21) | AV21: =CONCATENATE(IF(Y21="","",$Y$8),Y21) | AW21: =CONCATENATE(IF(Z21="","",$Z$8),Z21) | AX21: =CONCATENATE(IF(AA21="","",$AA$8),AA21) | AY21: =CONCATENATE(IF(AB21="","",AB$8),AB21) | AZ21: =CONCATENATE(IF(AC21="","",AC$8),AC21) | BA21: =CONCATENATE(IF(AD21="","",$AD$8),AD21) | BB21: =AND(BC21,BD21,BE21,BF21,BG21,BH21,BI21,BJ21,BK21,BL21,BM21,BN21,BO21,BP21,BQ21,BR21,BS21,BT21,BU21,BV21,BW21,BX21,BY21,BZ21,CA21) -> TRUE | BC21: =ISERROR(SEARCH("`",B21)) -> TRUE | BD21: =ISERROR(SEARCH("<",B21)) -> TRUE | BE21: =ISERROR(SEARCH(">",B21)) -> TRUE | BF21: =ISERROR(SEARCH(":",B21)) -> TRUE | BG21: =ISERROR(SEARCH(",",B21)) -> TRUE | BH21: =ISERROR(SEARCH(";",B21)) -> TRUE | BI21: =ISERROR(SEARCH("|",B21)) -> TRUE | BJ21: =ISERROR(SEARCH("\",B21)) -> TRUE | BK21: =ISERROR(SEARCH("[",B21)) -> TRUE | BL21: =ISERROR(SEARCH("]",B21)) -> TRUE | BM21: =ISERROR(SEARCH("{",B21)) -> TRUE | BN21: =ISERROR(SEARCH("}",B21)) -> TRUE | BO21: =ISERROR(SEARCH("_",B21)) -> TRUE | BP21: =ISERROR(SEARCH("(",B21)) -> TRUE | BQ21: =ISERROR(SEARCH(")",B21)) -> TRUE | BR21: =ISERROR(SEARCH("&",B21)) -> TRUE | BS21: =ISERROR(SEARCH("^",B21)) -> TRUE | BT21: =ISERROR(SEARCH("#",B21)) -> TRUE | BU21: =ISERROR(SEARCH("@",B21)) -> TRUE | BV21: =ISERROR(SEARCH("!",B21)) -> TRUE | BW21: =ISERROR(SEARCH("~?",B21)) -> TRUE | BX21: =ISERROR(SEARCH("~*",B21)) -> TRUE | BY21: =ISERROR(SEARCH("=",B21)) -> TRUE | BZ21: =ISERROR(SEARCH("""",B21)) -> TRUE | CA21: =ISERROR(SEARCH(" ",B21)) -> TRUE
A22: =CONCATENATE("*",B21,"$",D21-(DATE(YEAR(D21),1,1)-1),A21,F21,AH21,AI21,AJ21,AK21,AL21,AM21,AN21,AO21,AP21,AQ21,AR21,AS21,AT21,AU21,AV21,AW21,AX21,AY21,AZ21,BA21,"*") -> *$0* | S22: =CONCATENATE("*",C21,"*") -> ** | BB22: =AND(BC22,BD22,BE22,BF22,BG22,BH22,BI22,BJ22,BK22,BL22,BM22,BN22,BO22,BP22,BQ22,BR22,BS22,BT22,BU22,BV22,BW22,BX22,BY22,BZ22,CA22) -> TRUE | BC22: =ISERROR(SEARCH("`",D21)) -> TRUE | BD22: =ISERROR(SEARCH("<",D21)) -> TRUE | BE22: =ISERROR(SEARCH(">",D21)) -> TRUE | BF22: =ISERROR(SEARCH(":",D21)) -> TRUE | BG22: =ISERROR(SEARCH(",",D21)) -> TRUE | BH22: =ISERROR(SEARCH(";",D21)) -> TRUE | BI22: =ISERROR(SEARCH("|",D21)) -> TRUE | BJ22: =ISERROR(SEARCH("\",D21)) -> TRUE | BK22: =ISERROR(SEARCH("[",D21)) -> TRUE | BL22: =ISERROR(SEARCH("]",D21)) -> TRUE | BM22: =ISERROR(SEARCH("{",D21)) -> TRUE | BN22: =ISERROR(SEARCH("}",D21)) -> TRUE | BO22: =ISERROR(SEARCH("_",D21)) -> TRUE | BP22: =ISERROR(SEARCH("(",D21)) -> TRUE | BQ22: =ISERROR(SEARCH(")",D21)) -> TRUE | BR22: =ISERROR(SEARCH("&",D21)) -> TRUE | BS22: =ISERROR(SEARCH("^",D21)) -> TRUE | BT22: =ISERROR(SEARCH("#",D21)) -> TRUE | BU22: =ISERROR(SEARCH("@",D21)) -> TRUE | BV22: =ISERROR(SEARCH("!",D21)) -> TRUE | BW22: =ISERROR(SEARCH("~?",D21)) -> TRUE | BX22: =ISERROR(SEARCH("~*",D21)) -> TRUE | BY22: =ISERROR(SEARCH("=",D21)) -> TRUE | BZ22: =ISERROR(SEARCH("""",D21)) -> TRUE | CA22: =ISERROR(SEARCH(" ",D21)) -> TRUE
E23: 025/P | G23: =SUM(H23:AD23) -> 0 | AH23: =CONCATENATE(IF(H23="","",$H$8),H23) | AI23: =CONCATENATE(IF(I23="","",$I$8),I23) | AJ23: =CONCATENATE(IF(J23="","",$J$8),J23) | AK23: =CONCATENATE(IF(K23="","",$K$8),K23) | AL23: =CONCATENATE(IF(L23="","",$L$8),L23) | AM23: =CONCATENATE(IF(M23="","",$M$8),M23) | AN23: =CONCATENATE(IF(N23="","",$N$8),N23) | AO23: =CONCATENATE(IF(R23="","",$R$8),R23) | AP23: =CONCATENATE(IF(S23="","",$S$8),S23) | AQ23: =CONCATENATE(IF(T23="","",$T$8),T23) | AR23: =CONCATENATE(IF(U23="","",$U$8),U23) | AS23: =CONCATENATE(IF(V23="","",$V$8),V23) | AT23: =CONCATENATE(IF(W23="","",$W$8),W23) | AU23: =CONCATENATE(IF(X23="","",$X$8),X23) | AV23: =CONCATENATE(IF(Y23="","",$Y$8),Y23) | AW23: =CONCATENATE(IF(Z23="","",$Z$8),Z23) | AX23: =CONCATENATE(IF(AA23="","",$AA$8),AA23) | AY23: =CONCATENATE(IF(AB23="","",AB$8),AB23) | AZ23: =CONCATENATE(IF(AC23="","",AC$8),AC23) | BA23: =CONCATENATE(IF(AD23="","",$AD$8),AD23) | BB23: =AND(BC23,BD23,BE23,BF23,BG23,BH23,BI23,BJ23,BK23,BL23,BM23,BN23,BO23,BP23,BQ23,BR23,BS23,BT23,BU23,BV23,BW23,BX23,BY23,BZ23,CA23) -> TRUE | BC23: =ISERROR(SEARCH("`",B23)) -> TRUE | BD23: =ISERROR(SEARCH("<",B23)) -> TRUE | BE23: =ISERROR(SEARCH(">",B23)) -> TRUE | BF23: =ISERROR(SEARCH(":",B23)) -> TRUE | BG23: =ISERROR(SEARCH(",",B23)) -> TRUE | BH23: =ISERROR(SEARCH(";",B23)) -> TRUE | BI23: =ISERROR(SEARCH("|",B23)) -> TRUE | BJ23: =ISERROR(SEARCH("\",B23)) -> TRUE | BK23: =ISERROR(SEARCH("[",B23)) -> TRUE | BL23: =ISERROR(SEARCH("]",B23)) -> TRUE | BM23: =ISERROR(SEARCH("{",B23)) -> TRUE | BN23: =ISERROR(SEARCH("}",B23)) -> TRUE | BO23: =ISERROR(SEARCH("_",B23)) -> TRUE | BP23: =ISERROR(SEARCH("(",B23)) -> TRUE | BQ23: =ISERROR(SEARCH(")",B23)) -> TRUE | BR23: =ISERROR(SEARCH("&",B23)) -> TRUE | BS23: =ISERROR(SEARCH("^",B23)) -> TRUE | BT23: =ISERROR(SEARCH("#",B23)) -> TRUE | BU23: =ISERROR(SEARCH("@",B23)) -> TRUE | BV23: =ISERROR(SEARCH("!",B23)) -> TRUE | BW23: =ISERROR(SEARCH("~?",B23)) -> TRUE | BX23: =ISERROR(SEARCH("~*",B23)) -> TRUE | BY23: =ISERROR(SEARCH("=",B23)) -> TRUE | BZ23: =ISERROR(SEARCH("""",B23)) -> TRUE | CA23: =ISERROR(SEARCH(" ",B23)) -> TRUE
A24: =CONCATENATE("*",B23,"$",D23-(DATE(YEAR(D23),1,1)-1),A23,F23,AH23,AI23,AJ23,AK23,AL23,AM23,AN23,AO23,AP23,AQ23,AR23,AS23,AT23,AU23,AV23,AW23,AX23,AY23,AZ23,BA23,"*") -> *$0* | S24: =CONCATENATE("*",C23,"*") -> ** | BB24: =AND(BC24,BD24,BE24,BF24,BG24,BH24,BI24,BJ24,BK24,BL24,BM24,BN24,BO24,BP24,BQ24,BR24,BS24,BT24,BU24,BV24,BW24,BX24,BY24,BZ24,CA24) -> TRUE | BC24: =ISERROR(SEARCH("`",D23)) -> TRUE | BD24: =ISERROR(SEARCH("<",D23)) -> TRUE | BE24: =ISERROR(SEARCH(">",D23)) -> TRUE | BF24: =ISERROR(SEARCH(":",D23)) -> TRUE | BG24: =ISERROR(SEARCH(",",D23)) -> TRUE | BH24: =ISERROR(SEARCH(";",D23)) -> TRUE | BI24: =ISERROR(SEARCH("|",D23)) -> TRUE | BJ24: =ISERROR(SEARCH("\",D23)) -> TRUE | BK24: =ISERROR(SEARCH("[",D23)) -> TRUE | BL24: =ISERROR(SEARCH("]",D23)) -> TRUE | BM24: =ISERROR(SEARCH("{",D23)) -> TRUE | BN24: =ISERROR(SEARCH("}",D23)) -> TRUE | BO24: =ISERROR(SEARCH("_",D23)) -> TRUE | BP24: =ISERROR(SEARCH("(",D23)) -> TRUE | BQ24: =ISERROR(SEARCH(")",D23)) -> TRUE | BR24: =ISERROR(SEARCH("&",D23)) -> TRUE | BS24: =ISERROR(SEARCH("^",D23)) -> TRUE | BT24: =ISERROR(SEARCH("#",D23)) -> TRUE | BU24: =ISERROR(SEARCH("@",D23)) -> TRUE | BV24: =ISERROR(SEARCH("!",D23)) -> TRUE | BW24: =ISERROR(SEARCH("~?",D23)) -> TRUE | BX24: =ISERROR(SEARCH("~*",D23)) -> TRUE | BY24: =ISERROR(SEARCH("=",D23)) -> TRUE | BZ24: =ISERROR(SEARCH("""",D23)) -> TRUE | CA24: =ISERROR(SEARCH(" ",D23)) -> TRUE
E25: 025/P | G25: =SUM(H25:AD25) -> 0 | AH25: =CONCATENATE(IF(H25="","",$H$8),H25) | AI25: =CONCATENATE(IF(I25="","",$I$8),I25) | AJ25: =CONCATENATE(IF(J25="","",$J$8),J25) | AK25: =CONCATENATE(IF(K25="","",$K$8),K25) | AL25: =CONCATENATE(IF(L25="","",$L$8),L25) | AM25: =CONCATENATE(IF(M25="","",$M$8),M25) | AN25: =CONCATENATE(IF(N25="","",$N$8),N25) | AO25: =CONCATENATE(IF(R25="","",$R$8),R25) | AP25: =CONCATENATE(IF(S25="","",$S$8),S25) | AQ25: =CONCATENATE(IF(T25="","",$T$8),T25) | AR25: =CONCATENATE(IF(U25="","",$U$8),U25) | AS25: =CONCATENATE(IF(V25="","",$V$8),V25) | AT25: =CONCATENATE(IF(W25="","",$W$8),W25) | AU25: =CONCATENATE(IF(X25="","",$X$8),X25) | AV25: =CONCATENATE(IF(Y25="","",$Y$8),Y25) | AW25: =CONCATENATE(IF(Z25="","",$Z$8),Z25) | AX25: =CONCATENATE(IF(AA25="","",$AA$8),AA25) | AY25: =CONCATENATE(IF(AB25="","",AB$8),AB25) | AZ25: =CONCATENATE(IF(AC25="","",AC$8),AC25) | BA25: =CONCATENATE(IF(AD25="","",$AD$8),AD25) | BB25: =AND(BC25,BD25,BE25,BF25,BG25,BH25,BI25,BJ25,BK25,BL25,BM25,BN25,BO25,BP25,BQ25,BR25,BS25,BT25,BU25,BV25,BW25,BX25,BY25,BZ25,CA25) -> TRUE | BC25: =ISERROR(SEARCH("`",B25)) -> TRUE | BD25: =ISERROR(SEARCH("<",B25)) -> TRUE | BE25: =ISERROR(SEARCH(">",B25)) -> TRUE | BF25: =ISERROR(SEARCH(":",B25)) -> TRUE | BG25: =ISERROR(SEARCH(",",B25)) -> TRUE | BH25: =ISERROR(SEARCH(";",B25)) -> TRUE | BI25: =ISERROR(SEARCH("|",B25)) -> TRUE | BJ25: =ISERROR(SEARCH("\",B25)) -> TRUE | BK25: =ISERROR(SEARCH("[",B25)) -> TRUE | BL25: =ISERROR(SEARCH("]",B25)) -> TRUE | BM25: =ISERROR(SEARCH("{",B25)) -> TRUE | BN25: =ISERROR(SEARCH("}",B25)) -> TRUE | BO25: =ISERROR(SEARCH("_",B25)) -> TRUE | BP25: =ISERROR(SEARCH("(",B25)) -> TRUE | BQ25: =ISERROR(SEARCH(")",B25)) -> TRUE | BR25: =ISERROR(SEARCH("&",B25)) -> TRUE | BS25: =ISERROR(SEARCH("^",B25)) -> TRUE | BT25: =ISERROR(SEARCH("#",B25)) -> TRUE | BU25: =ISERROR(SEARCH("@",B25)) -> TRUE | BV25: =ISERROR(SEARCH("!",B25)) -> TRUE | BW25: =ISERROR(SEARCH("~?",B25)) -> TRUE | BX25: =ISERROR(SEARCH("~*",B25)) -> TRUE | BY25: =ISERROR(SEARCH("=",B25)) -> TRUE | BZ25: =ISERROR(SEARCH("""",B25)) -> TRUE | CA25: =ISERROR(SEARCH(" ",B25)) -> TRUE
A26: =CONCATENATE("*",B25,"$",D25-(DATE(YEAR(D25),1,1)-1),A25,F25,AH25,AI25,AJ25,AK25,AL25,AM25,AN25,AO25,AP25,AQ25,AR25,AS25,AT25,AU25,AV25,AW25,AX25,AY25,AZ25,BA25,"*") -> *$0* | S26: =CONCATENATE("*",C25,"*") -> ** | BB26: =AND(BC26,BD26,BE26,BF26,BG26,BH26,BI26,BJ26,BK26,BL26,BM26,BN26,BO26,BP26,BQ26,BR26,BS26,BT26,BU26,BV26,BW26,BX26,BY26,BZ26,CA26) -> TRUE | BC26: =ISERROR(SEARCH("`",D25)) -> TRUE | BD26: =ISERROR(SEARCH("<",D25)) -> TRUE | BE26: =ISERROR(SEARCH(">",D25)) -> TRUE | BF26: =ISERROR(SEARCH(":",D25)) -> TRUE | BG26: =ISERROR(SEARCH(",",D25)) -> TRUE | BH26: =ISERROR(SEARCH(";",D25)) -> TRUE | BI26: =ISERROR(SEARCH("|",D25)) -> TRUE | BJ26: =ISERROR(SEARCH("\",D25)) -> TRUE | BK26: =ISERROR(SEARCH("[",D25)) -> TRUE | BL26: =ISERROR(SEARCH("]",D25)) -> TRUE | BM26: =ISERROR(SEARCH("{",D25)) -> TRUE | BN26: =ISERROR(SEARCH("}",D25)) -> TRUE | BO26: =ISERROR(SEARCH("_",D25)) -> TRUE | BP26: =ISERROR(SEARCH("(",D25)) -> TRUE | BQ26: =ISERROR(SEARCH(")",D25)) -> TRUE | BR26: =ISERROR(SEARCH("&",D25)) -> TRUE | BS26: =ISERROR(SEARCH("^",D25)) -> TRUE | BT26: =ISERROR(SEARCH("#",D25)) -> TRUE | BU26: =ISERROR(SEARCH("@",D25)) -> TRUE | BV26: =ISERROR(SEARCH("!",D25)) -> TRUE | BW26: =ISERROR(SEARCH("~?",D25)) -> TRUE | BX26: =ISERROR(SEARCH("~*",D25)) -> TRUE | BY26: =ISERROR(SEARCH("=",D25)) -> TRUE | BZ26: =ISERROR(SEARCH("""",D25)) -> TRUE | CA26: =ISERROR(SEARCH(" ",D25)) -> TRUE
E27: 025/P | G27: =SUM(H27:AD27) -> 0 | AH27: =CONCATENATE(IF(H27="","",$H$8),H27) | AI27: =CONCATENATE(IF(I27="","",$I$8),I27) | AJ27: =CONCATENATE(IF(J27="","",$J$8),J27) | AK27: =CONCATENATE(IF(K27="","",$K$8),K27) | AL27: =CONCATENATE(IF(L27="","",$L$8),L27) | AM27: =CONCATENATE(IF(M27="","",$M$8),M27) | AN27: =CONCATENATE(IF(N27="","",$N$8),N27) | AO27: =CONCATENATE(IF(R27="","",$R$8),R27) | AP27: =CONCATENATE(IF(S27="","",$S$8),S27) | AQ27: =CONCATENATE(IF(T27="","",$T$8),T27) | AR27: =CONCATENATE(IF(U27="","",$U$8),U27) | AS27: =CONCATENATE(IF(V27="","",$V$8),V27) | AT27: =CONCATENATE(IF(W27="","",$W$8),W27) | AU27: =CONCATENATE(IF(X27="","",$X$8),X27) | AV27: =CONCATENATE(IF(Y27="","",$Y$8),Y27) | AW27: =CONCATENATE(IF(Z27="","",$Z$8),Z27) | AX27: =CONCATENATE(IF(AA27="","",$AA$8),AA27) | AY27: =CONCATENATE(IF(AB27="","",AB$8),AB27) | AZ27: =CONCATENATE(IF(AC27="","",AC$8),AC27) | BA27: =CONCATENATE(IF(AD27="","",$AD$8),AD27) | BB27: =AND(BC27,BD27,BE27,BF27,BG27,BH27,BI27,BJ27,BK27,BL27,BM27,BN27,BO27,BP27,BQ27,BR27,BS27,BT27,BU27,BV27,BW27,BX27,BY27,BZ27,CA27) -> TRUE | BC27: =ISERROR(SEARCH("`",B27)) -> TRUE | BD27: =ISERROR(SEARCH("<",B27)) -> TRUE | BE27: =ISERROR(SEARCH(">",B27)) -> TRUE | BF27: =ISERROR(SEARCH(":",B27)) -> TRUE | BG27: =ISERROR(SEARCH(",",B27)) -> TRUE | BH27: =ISERROR(SEARCH(";",B27)) -> TRUE | BI27: =ISERROR(SEARCH("|",B27)) -> TRUE | BJ27: =ISERROR(SEARCH("\",B27)) -> TRUE | BK27: =ISERROR(SEARCH("[",B27)) -> TRUE | BL27: =ISERROR(SEARCH("]",B27)) -> TRUE | BM27: =ISERROR(SEARCH("{",B27)) -> TRUE | BN27: =ISERROR(SEARCH("}",B27)) -> TRUE | BO27: =ISERROR(SEARCH("_",B27)) -> TRUE | BP27: =ISERROR(SEARCH("(",B27)) -> TRUE | BQ27: =ISERROR(SEARCH(")",B27)) -> TRUE | BR27: =ISERROR(SEARCH("&",B27)) -> TRUE | BS27: =ISERROR(SEARCH("^",B27)) -> TRUE | BT27: =ISERROR(SEARCH("#",B27)) -> TRUE | BU27: =ISERROR(SEARCH("@",B27)) -> TRUE | BV27: =ISERROR(SEARCH("!",B27)) -> TRUE | BW27: =ISERROR(SEARCH("~?",B27)) -> TRUE | BX27: =ISERROR(SEARCH("~*",B27)) -> TRUE | BY27: =ISERROR(SEARCH("=",B27)) -> TRUE | BZ27: =ISERROR(SEARCH("""",B27)) -> TRUE | CA27: =ISERROR(SEARCH(" ",B27)) -> TRUE
A28: =CONCATENATE("*",B27,"$",D27-(DATE(YEAR(D27),1,1)-1),A27,F27,AH27,AI27,AJ27,AK27,AL27,AM27,AN27,AO27,AP27,AQ27,AR27,AS27,AT27,AU27,AV27,AW27,AX27,AY27,AZ27,BA27,"*") -> *$0* | S28: =CONCATENATE("*",C27,"*") -> ** | BB28: =AND(BC28,BD28,BE28,BF28,BG28,BH28,BI28,BJ28,BK28,BL28,BM28,BN28,BO28,BP28,BQ28,BR28,BS28,BT28,BU28,BV28,BW28,BX28,BY28,BZ28,CA28) -> TRUE | BC28: =ISERROR(SEARCH("`",D27)) -> TRUE | BD28: =ISERROR(SEARCH("<",D27)) -> TRUE | BE28: =ISERROR(SEARCH(">",D27)) -> TRUE | BF28: =ISERROR(SEARCH(":",D27)) -> TRUE | BG28: =ISERROR(SEARCH(",",D27)) -> TRUE | BH28: =ISERROR(SEARCH(";",D27)) -> TRUE | BI28: =ISERROR(SEARCH("|",D27)) -> TRUE | BJ28: =ISERROR(SEARCH("\",D27)) -> TRUE | BK28: =ISERROR(SEARCH("[",D27)) -> TRUE | BL28: =ISERROR(SEARCH("]",D27)) -> TRUE | BM28: =ISERROR(SEARCH("{",D27)) -> TRUE | BN28: =ISERROR(SEARCH("}",D27)) -> TRUE | BO28: =ISERROR(SEARCH("_",D27)) -> TRUE | BP28: =ISERROR(SEARCH("(",D27)) -> TRUE | BQ28: =ISERROR(SEARCH(")",D27)) -> TRUE | BR28: =ISERROR(SEARCH("&",D27)) -> TRUE | BS28: =ISERROR(SEARCH("^",D27)) -> TRUE | BT28: =ISERROR(SEARCH("#",D27)) -> TRUE | BU28: =ISERROR(SEARCH("@",D27)) -> TRUE | BV28: =ISERROR(SEARCH("!",D27)) -> TRUE | BW28: =ISERROR(SEARCH("~?",D27)) -> TRUE | BX28: =ISERROR(SEARCH("~*",D27)) -> TRUE | BY28: =ISERROR(SEARCH("=",D27)) -> TRUE | BZ28: =ISERROR(SEARCH("""",D27)) -> TRUE | CA28: =ISERROR(SEARCH(" ",D27)) -> TRUE
E29: 025/P | G29: =SUM(H29:AD29) -> 0 | AH29: =CONCATENATE(IF(H29="","",$H$8),H29) | AI29: =CONCATENATE(IF(I29="","",$I$8),I29) | AJ29: =CONCATENATE(IF(J29="","",$J$8),J29) | AK29: =CONCATENATE(IF(K29="","",$K$8),K29) | AL29: =CONCATENATE(IF(L29="","",$L$8),L29) | AM29: =CONCATENATE(IF(M29="","",$M$8),M29) | AN29: =CONCATENATE(IF(N29="","",$N$8),N29) | AO29: =CONCATENATE(IF(R29="","",$R$8),R29) | AP29: =CONCATENATE(IF(S29="","",$S$8),S29) | AQ29: =CONCATENATE(IF(T29="","",$T$8),T29) | AR29: =CONCATENATE(IF(U29="","",$U$8),U29) | AS29: =CONCATENATE(IF(V29="","",$V$8),V29) | AT29: =CONCATENATE(IF(W29="","",$W$8),W29) | AU29: =CONCATENATE(IF(X29="","",$X$8),X29) | AV29: =CONCATENATE(IF(Y29="","",$Y$8),Y29) | AW29: =CONCATENATE(IF(Z29="","",$Z$8),Z29) | AX29: =CONCATENATE(IF(AA29="","",$AA$8),AA29) | AY29: =CONCATENATE(IF(AB29="","",AB$8),AB29) | AZ29: =CONCATENATE(IF(AC29="","",AC$8),AC29) | BA29: =CONCATENATE(IF(AD29="","",$AD$8),AD29) | BB29: =AND(BC29,BD29,BE29,BF29,BG29,BH29,BI29,BJ29,BK29,BL29,BM29,BN29,BO29,BP29,BQ29,BR29,BS29,BT29,BU29,BV29,BW29,BX29,BY29,BZ29,CA29) -> TRUE | BC29: =ISERROR(SEARCH("`",B29)) -> TRUE | BD29: =ISERROR(SEARCH("<",B29)) -> TRUE | BE29: =ISERROR(SEARCH(">",B29)) -> TRUE | BF29: =ISERROR(SEARCH(":",B29)) -> TRUE | BG29: =ISERROR(SEARCH(",",B29)) -> TRUE | BH29: =ISERROR(SEARCH(";",B29)) -> TRUE | BI29: =ISERROR(SEARCH("|",B29)) -> TRUE | BJ29: =ISERROR(SEARCH("\",B29)) -> TRUE | BK29: =ISERROR(SEARCH("[",B29)) -> TRUE | BL29: =ISERROR(SEARCH("]",B29)) -> TRUE | BM29: =ISERROR(SEARCH("{",B29)) -> TRUE | BN29: =ISERROR(SEARCH("}",B29)) -> TRUE | BO29: =ISERROR(SEARCH("_",B29)) -> TRUE | BP29: =ISERROR(SEARCH("(",B29)) -> TRUE | BQ29: =ISERROR(SEARCH(")",B29)) -> TRUE | BR29: =ISERROR(SEARCH("&",B29)) -> TRUE | BS29: =ISERROR(SEARCH("^",B29)) -> TRUE | BT29: =ISERROR(SEARCH("#",B29)) -> TRUE | BU29: =ISERROR(SEARCH("@",B29)) -> TRUE | BV29: =ISERROR(SEARCH("!",B29)) -> TRUE | BW29: =ISERROR(SEARCH("~?",B29)) -> TRUE | BX29: =ISERROR(SEARCH("~*",B29)) -> TRUE | BY29: =ISERROR(SEARCH("=",B29)) -> TRUE | BZ29: =ISERROR(SEARCH("""",B29)) -> TRUE | CA29: =ISERROR(SEARCH(" ",B29)) -> TRUE
A30: =CONCATENATE("*",B29,"$",D29-(DATE(YEAR(D29),1,1)-1),A29,F29,AH29,AI29,AJ29,AK29,AL29,AM29,AN29,AO29,AP29,AQ29,AR29,AS29,AT29,AU29,AV29,AW29,AX29,AY29,AZ29,BA29,"*") -> *$0* | S30: =CONCATENATE("*",C29,"*") -> ** | BB30: =AND(BC30,BD30,BE30,BF30,BG30,BH30,BI30,BJ30,BK30,BL30,BM30,BN30,BO30,BP30,BQ30,BR30,BS30,BT30,BU30,BV30,BW30,BX30,BY30,BZ30,CA30) -> TRUE | BC30: =ISERROR(SEARCH("`",D29)) -> TRUE | BD30: =ISERROR(SEARCH("<",D29)) -> TRUE | BE30: =ISERROR(SEARCH(">",D29)) -> TRUE | BF30: =ISERROR(SEARCH(":",D29)) -> TRUE | BG30: =ISERROR(SEARCH(",",D29)) -> TRUE | BH30: =ISERROR(SEARCH(";",D29)) -> TRUE | BI30: =ISERROR(SEARCH("|",D29)) -> TRUE | BJ30: =ISERROR(SEARCH("\",D29)) -> TRUE | BK30: =ISERROR(SEARCH("[",D29)) -> TRUE | BL30: =ISERROR(SEARCH("]",D29)) -> TRUE | BM30: =ISERROR(SEARCH("{",D29)) -> TRUE | BN30: =ISERROR(SEARCH("}",D29)) -> TRUE | BO30: =ISERROR(SEARCH("_",D29)) -> TRUE | BP30: =ISERROR(SEARCH("(",D29)) -> TRUE | BQ30: =ISERROR(SEARCH(")",D29)) -> TRUE | BR30: =ISERROR(SEARCH("&",D29)) -> TRUE | BS30: =ISERROR(SEARCH("^",D29)) -> TRUE | BT30: =ISERROR(SEARCH("#",D29)) -> TRUE | BU30: =ISERROR(SEARCH("@",D29)) -> TRUE | BV30: =ISERROR(SEARCH("!",D29)) -> TRUE | BW30: =ISERROR(SEARCH("~?",D29)) -> TRUE | BX30: =ISERROR(SEARCH("~*",D29)) -> TRUE | BY30: =ISERROR(SEARCH("=",D29)) -> TRUE | BZ30: =ISERROR(SEARCH("""",D29)) -> TRUE | CA30: =ISERROR(SEARCH(" ",D29)) -> TRUE
E31: 025/P | G31: =SUM(H31:AD31) -> 0 | AH31: =CONCATENATE(IF(H31="","",$H$8),H31) | AI31: =CONCATENATE(IF(I31="","",$I$8),I31) | AL31: =CONCATENATE(IF(L31="","",$L$8),L31) | AM31: =CONCATENATE(IF(M31="","",$M$8),M31) | AN31: =CONCATENATE(IF(N31="","",$N$8),N31) | AO31: =CONCATENATE(IF(R31="","",$R$8),R31) | AP31: =CONCATENATE(IF(S31="","",$S$8),S31) | AQ31: =CONCATENATE(IF(T31="","",$T$8),T31) | AR31: =CONCATENATE(IF(U31="","",$U$8),U31) | AS31: =CONCATENATE(IF(V31="","",$V$8),V31) | AT31: =CONCATENATE(IF(W31="","",$W$8),W31) | AU31: =CONCATENATE(IF(X31="","",$X$8),X31) | AV31: =CONCATENATE(IF(Y31="","",$Y$8),Y31) | AW31: =CONCATENATE(IF(Z31="","",$Z$8),Z31) | AX31: =CONCATENATE(IF(AA31="","",$AA$8),AA31) | AY31: =CONCATENATE(IF(AB31="","",AB$8),AB31) | AZ31: =CONCATENATE(IF(AC31="","",AC$8),AC31) | BA31: =CONCATENATE(IF(AD31="","",$AD$8),AD31) | BB31: =AND(BC31,BD31,BE31,BF31,BG31,BH31,BI31,BJ31,BK31,BL31,BM31,BN31,BO31,BP31,BQ31,BR31,BS31,BT31,BU31,BV31,BW31,BX31,BY31,BZ31,CA31) -> TRUE | BC31: =ISERROR(SEARCH("`",B31)) -> TRUE | BD31: =ISERROR(SEARCH("<",B31)) -> TRUE | BE31: =ISERROR(SEARCH(">",B31)) -> TRUE | BF31: =ISERROR(SEARCH(":",B31)) -> TRUE | BG31: =ISERROR(SEARCH(",",B31)) -> TRUE | BH31: =ISERROR(SEARCH(";",B31)) -> TRUE | BI31: =ISERROR(SEARCH("|",B31)) -> TRUE | BJ31: =ISERROR(SEARCH("\",B31)) -> TRUE | BK31: =ISERROR(SEARCH("[",B31)) -> TRUE | BL31: =ISERROR(SEARCH("]",B31)) -> TRUE | BM31: =ISERROR(SEARCH("{",B31)) -> TRUE | BN31: =ISERROR(SEARCH("}",B31)) -> TRUE | BO31: =ISERROR(SEARCH("_",B31)) -> TRUE | BP31: =ISERROR(SEARCH("(",B31)) -> TRUE | BQ31: =ISERROR(SEARCH(")",B31)) -> TRUE | BR31: =ISERROR(SEARCH("&",B31)) -> TRUE | BS31: =ISERROR(SEARCH("^",B31)) -> TRUE | BT31: =ISERROR(SEARCH("#",B31)) -> TRUE | BU31: =ISERROR(SEARCH("@",B31)) -> TRUE | BV31: =ISERROR(SEARCH("!",B31)) -> TRUE | BW31: =ISERROR(SEARCH("~?",B31)) -> TRUE | BX31: =ISERROR(SEARCH("~*",B31)) -> TRUE | BY31: =ISERROR(SEARCH("=",B31)) -> TRUE | BZ31: =ISERROR(SEARCH("""",B31)) -> TRUE | CA31: =ISERROR(SEARCH(" ",B31)) -> TRUE
A32: =CONCATENATE("*",B31,"$",D31-(DATE(YEAR(D31),1,1)-1),A31,F31,AH31,AI31,AJ31,AK31,AL31,AM31,AN31,AO31,AP31,AQ31,AR31,AS31,AT31,AU31,AV31,AW31,AX31,AY31,"*") -> *$0* | S32: =CONCATENATE("*",C31,"*") -> ** | BB32: =AND(BC32,BD32,BE32,BF32,BG32,BH32,BI32,BJ32,BK32,BL32,BM32,BN32,BO32,BP32,BQ32,BR32,BS32,BT32,BU32,BV32,BW32,BX32,BY32,BZ32,CA32) -> TRUE | BC32: =ISERROR(SEARCH("`",D31)) -> TRUE | BD32: =ISERROR(SEARCH("<",D31)) -> TRUE | BE32: =ISERROR(SEARCH(">",D31)) -> TRUE | BF32: =ISERROR(SEARCH(":",D31)) -> TRUE | BG32: =ISERROR(SEARCH(",",D31)) -> TRUE | BH32: =ISERROR(SEARCH(";",D31)) -> TRUE | BI32: =ISERROR(SEARCH("|",D31)) -> TRUE | BJ32: =ISERROR(SEARCH("\",D31)) -> TRUE | BK32: =ISERROR(SEARCH("[",D31)) -> TRUE | BL32: =ISERROR(SEARCH("]",D31)) -> TRUE | BM32: =ISERROR(SEARCH("{",D31)) -> TRUE | BN32: =ISERROR(SEARCH("}",D31)) -> TRUE | BO32: =ISERROR(SEARCH("_",D31)) -> TRUE | BP32: =ISERROR(SEARCH("(",D31)) -> TRUE | BQ32: =ISERROR(SEARCH(")",D31)) -> TRUE | BR32: =ISERROR(SEARCH("&",D31)) -> TRUE | BS32: =ISERROR(SEARCH("^",D31)) -> TRUE | BT32: =ISERROR(SEARCH("#",D31)) -> TRUE | BU32: =ISERROR(SEARCH("@",D31)) -> TRUE | BV32: =ISERROR(SEARCH("!",D31)) -> TRUE | BW32: =ISERROR(SEARCH("~?",D31)) -> TRUE | BX32: =ISERROR(SEARCH("~*",D31)) -> TRUE | BY32: =ISERROR(SEARCH("=",D31)) -> TRUE | BZ32: =ISERROR(SEARCH("""",D31)) -> TRUE | CA32: =ISERROR(SEARCH(" ",D31)) -> TRUE
E33: 025/P | G33: =SUM(H33:AD33) -> 0 | AH33: =CONCATENATE(IF(H33="","",$H$8),H33) | AN33: =CONCATENATE(IF(N33="","",$N$8),N33) | AO33: =CONCATENATE(IF(R33="","",$R$8),R33) | AP33: =CONCATENATE(IF(S33="","",$S$8),S33) | AQ33: =CONCATENATE(IF(T33="","",$T$8),T33) | AR33: =CONCATENATE(IF(U33="","",$U$8),U33) | AS33: =CONCATENATE(IF(V33="","",$V$8),V33) | AT33: =CONCATENATE(IF(W33="","",$W$8),W33) | AU33: =CONCATENATE(IF(X33="","",$X$8),X33) | AV33: =CONCATENATE(IF(Y33="","",$Y$8),Y33) | AW33: =CONCATENATE(IF(Z33="","",$Z$8),Z33) | AX33: =CONCATENATE(IF(AA33="","",$AA$8),AA33) | AY33: =CONCATENATE(IF(AB33="","",AB$8),AB33) | AZ33: =CONCATENATE(IF(AC33="","",AC$8),AC33) | BA33: =CONCATENATE(IF(AD33="","",$AD$8),AD33) | BB33: =AND(BC33,BD33,BE33,BF33,BG33,BH33,BI33,BJ33,BK33,BL33,BM33,BN33,BO33,BP33,BQ33,BR33,BS33,BT33,BU33,BV33,BW33,BX33,BY33,BZ33,CA33) -> TRUE | BC33: =ISERROR(SEARCH("`",B33)) -> TRUE | BD33: =ISERROR(SEARCH("<",B33)) -> TRUE | BE33: =ISERROR(SEARCH(">",B33)) -> TRUE | BF33: =ISERROR(SEARCH(":",B33)) -> TRUE | BG33: =ISERROR(SEARCH(",",B33)) -> TRUE | BH33: =ISERROR(SEARCH(";",B33)) -> TRUE | BI33: =ISERROR(SEARCH("|",B33)) -> TRUE | BJ33: =ISERROR(SEARCH("\",B33)) -> TRUE | BK33: =ISERROR(SEARCH("[",B33)) -> TRUE | BL33: =ISERROR(SEARCH("]",B33)) -> TRUE | BM33: =ISERROR(SEARCH("{",B33)) -> TRUE | BN33: =ISERROR(SEARCH("}",B33)) -> TRUE | BO33: =ISERROR(SEARCH("_",B33)) -> TRUE | BP33: =ISERROR(SEARCH("(",B33)) -> TRUE | BQ33: =ISERROR(SEARCH(")",B33)) -> TRUE | BR33: =ISERROR(SEARCH("&",B33)) -> TRUE | BS33: =ISERROR(SEARCH("^",B33)) -> TRUE | BT33: =ISERROR(SEARCH("#",B33)) -> TRUE | BU33: =ISERROR(SEARCH("@",B33)) -> TRUE | BV33: =ISERROR(SEARCH("!",B33)) -> TRUE | BW33: =ISERROR(SEARCH("~?",B33)) -> TRUE | BX33: =ISERROR(SEARCH("~*",B33)) -> TRUE | BY33: =ISERROR(SEARCH("=",B33)) -> TRUE | BZ33: =ISERROR(SEARCH("""",B33)) -> TRUE | CA33: =ISERROR(SEARCH(" ",B33)) -> TRUE
A34: =CONCATENATE("*",B33,"$",D33-(DATE(YEAR(D33),1,1)-1),A33,F33,AH33,AI33,AJ33,AK33,AL33,AM33,AN33,AO33,AP33,AQ33,AR33,AS33,AT33,AU33,AV33,AW33,AX33,AY33,"*") -> *$0* | S34: =CONCATENATE("*",C33,"*") -> ** | BB34: =AND(BC34,BD34,BE34,BF34,BG34,BH34,BI34,BJ34,BK34,BL34,BM34,BN34,BO34,BP34,BQ34,BR34,BS34,BT34,BU34,BV34,BW34,BX34,BY34,BZ34,CA34) -> TRUE | BC34: =ISERROR(SEARCH("`",D33)) -> TRUE | BD34: =ISERROR(SEARCH("<",D33)) -> TRUE | BE34: =ISERROR(SEARCH(">",D33)) -> TRUE | BF34: =ISERROR(SEARCH(":",D33)) -> TRUE | BG34: =ISERROR(SEARCH(",",D33)) -> TRUE | BH34: =ISERROR(SEARCH(";",D33)) -> TRUE | BI34: =ISERROR(SEARCH("|",D33)) -> TRUE | BJ34: =ISERROR(SEARCH("\",D33)) -> TRUE | BK34: =ISERROR(SEARCH("[",D33)) -> TRUE | BL34: =ISERROR(SEARCH("]",D33)) -> TRUE | BM34: =ISERROR(SEARCH("{",D33)) -> TRUE | BN34: =ISERROR(SEARCH("}",D33)) -> TRUE | BO34: =ISERROR(SEARCH("_",D33)) -> TRUE | BP34: =ISERROR(SEARCH("(",D33)) -> TRUE | BQ34: =ISERROR(SEARCH(")",D33)) -> TRUE | BR34: =ISERROR(SEARCH("&",D33)) -> TRUE | BS34: =ISERROR(SEARCH("^",D33)) -> TRUE | BT34: =ISERROR(SEARCH("#",D33)) -> TRUE | BU34: =ISERROR(SEARCH("@",D33)) -> TRUE | BV34: =ISERROR(SEARCH("!",D33)) -> TRUE | BW34: =ISERROR(SEARCH("~?",D33)) -> TRUE | BX34: =ISERROR(SEARCH("~*",D33)) -> TRUE | BY34: =ISERROR(SEARCH("=",D33)) -> TRUE | BZ34: =ISERROR(SEARCH("""",D33)) -> TRUE | CA34: =ISERROR(SEARCH(" ",D33)) -> TRUE
E35: 025/P | G35: =SUM(H35:AD35) -> 0 | AH35: =CONCATENATE(IF(H35="","",$H$8),H35) | AI35: =CONCATENATE(IF(I35="","",$I$8),I35) | AJ35: =CONCATENATE(IF(J35="","",$J$8),J35) | AK35: =CONCATENATE(IF(K35="","",$K$8),K35) | AL35: =CONCATENATE(IF(L35="","",$L$8),L35) | AM35: =CONCATENATE(IF(M35="","",$M$8),M35) | AN35: =CONCATENATE(IF(N35="","",$N$8),N35) | AO35: =CONCATENATE(IF(R35="","",$R$8),R35) | AP35: =CONCATENATE(IF(S35="","",$S$8),S35) | AQ35: =CONCATENATE(IF(T35="","",$T$8),T35) | AR35: =CONCATENATE(IF(U35="","",$U$8),U35) | AS35: =CONCATENATE(IF(V35="","",$V$8),V35) | AT35: =CONCATENATE(IF(W35="","",$W$8),W35) | AU35: =CONCATENATE(IF(X35="","",$X$8),X35) | AV35: =CONCATENATE(IF(Y35="","",$Y$8),Y35) | AW35: =CONCATENATE(IF(Z35="","",$Z$8),Z35) | AX35: =CONCATENATE(IF(AA35="","",$AA$8),AA35) | AY35: =CONCATENATE(IF(AB35="","",AB$8),AB35) | AZ35: =CONCATENATE(IF(AC35="","",AC$8),AC35) | BA35: =CONCATENATE(IF(AD35="","",$AD$8),AD35) | BB35: =AND(BC35,BD35,BE35,BF35,BG35,BH35,BI35,BJ35,BK35,BL35,BM35,BN35,BO35,BP35,BQ35,BR35,BS35,BT35,BU35,BV35,BW35,BX35,BY35,BZ35,CA35) -> TRUE | BC35: =ISERROR(SEARCH("`",B35)) -> TRUE | BD35: =ISERROR(SEARCH("<",B35)) -> TRUE | BE35: =ISERROR(SEARCH(">",B35)) -> TRUE | BF35: =ISERROR(SEARCH(":",B35)) -> TRUE | BG35: =ISERROR(SEARCH(",",B35)) -> TRUE | BH35: =ISERROR(SEARCH(";",B35)) -> TRUE | BI35: =ISERROR(SEARCH("|",B35)) -> TRUE | BJ35: =ISERROR(SEARCH("\",B35)) -> TRUE | BK35: =ISERROR(SEARCH("[",B35)) -> TRUE | BL35: =ISERROR(SEARCH("]",B35)) -> TRUE | BM35: =ISERROR(SEARCH("{",B35)) -> TRUE | BN35: =ISERROR(SEARCH("}",B35)) -> TRUE | BO35: =ISERROR(SEARCH("_",B35)) -> TRUE | BP35: =ISERROR(SEARCH("(",B35)) -> TRUE | BQ35: =ISERROR(SEARCH(")",B35)) -> TRUE | BR35: =ISERROR(SEARCH("&",B35)) -> TRUE | BS35: =ISERROR(SEARCH("^",B35)) -> TRUE | BT35: =ISERROR(SEARCH("#",B35)) -> TRUE | BU35: =ISERROR(SEARCH("@",B35)) -> TRUE | BV35: =ISERROR(SEARCH("!",B35)) -> TRUE | BW35: =ISERROR(SEARCH("~?",B35)) -> TRUE | BX35: =ISERROR(SEARCH("~*",B35)) -> TRUE | BY35: =ISERROR(SEARCH("=",B35)) -> TRUE | BZ35: =ISERROR(SEARCH("""",B35)) -> TRUE | CA35: =ISERROR(SEARCH(" ",B35)) -> TRUE
A36: =CONCATENATE("*",B35,"$",D35-(DATE(YEAR(D35),1,1)-1),A35,F35,AH35,AI35,AJ35,AK35,AL35,AM35,AN35,AO35,AP35,AQ35,AR35,AS35,AT35,AU35,AV35,AW35,AX35,AY35,"*") -> *$0* | S36: =CONCATENATE("*",C35,"*") -> ** | BB36: =AND(BC36,BD36,BE36,BF36,BG36,BH36,BI36,BJ36,BK36,BL36,BM36,BN36,BO36,BP36,BQ36,BR36,BS36,BT36,BU36,BV36,BW36,BX36,BY36,BZ36,CA36) -> TRUE | BC36: =ISERROR(SEARCH("`",D35)) -> TRUE | BD36: =ISERROR(SEARCH("<",D35)) -> TRUE | BE36: =ISERROR(SEARCH(">",D35)) -> TRUE | BF36: =ISERROR(SEARCH(":",D35)) -> TRUE | BG36: =ISERROR(SEARCH(",",D35)) -> TRUE | BH36: =ISERROR(SEARCH(";",D35)) -> TRUE | BI36: =ISERROR(SEARCH("|",D35)) -> TRUE | BJ36: =ISERROR(SEARCH("\",D35)) -> TRUE | BK36: =ISERROR(SEARCH("[",D35)) -> TRUE | BL36: =ISERROR(SEARCH("]",D35)) -> TRUE | BM36: =ISERROR(SEARCH("{",D35)) -> TRUE | BN36: =ISERROR(SEARCH("}",D35)) -> TRUE | BO36: =ISERROR(SEARCH("_",D35)) -> TRUE | BP36: =ISERROR(SEARCH("(",D35)) -> TRUE | BQ36: =ISERROR(SEARCH(")",D35)) -> TRUE | BR36: =ISERROR(SEARCH("&",D35)) -> TRUE | BS36: =ISERROR(SEARCH("^",D35)) -> TRUE | BT36: =ISERROR(SEARCH("#",D35)) -> TRUE | BU36: =ISERROR(SEARCH("@",D35)) -> TRUE | BV36: =ISERROR(SEARCH("!",D35)) -> TRUE | BW36: =ISERROR(SEARCH("~?",D35)) -> TRUE | BX36: =ISERROR(SEARCH("~*",D35)) -> TRUE | BY36: =ISERROR(SEARCH("=",D35)) -> TRUE | BZ36: =ISERROR(SEARCH("""",D35)) -> TRUE | CA36: =ISERROR(SEARCH(" ",D35)) -> TRUE
A38: Kody braków
A39: A - Niedopełnienia | G39: B - Pęcherze powietrza | S39: C - Wtrącenia
A40: D - Uszkodzona forma | G40: E - Przypalenia | S40: F - Zabrudzona forma
A41: G - Pęknięcia | G41: H - Wada wymiarowa | S41: I - Niewłaściwy kolor kod, off set, Uszkodzenia CRIO
A42: K - Niedowulkanizowania | G42: L - Zanieczyszczenia/ odbarwienia | S42: M - Metal nie połączony z gumą
...

Sheet Braki_z_kodami - firmy zewn.
C1: Dzienny rejestr ruchów wyrobów | U1: Numer: F.QA.04.01.02 | AG1: Plus | AH1: Kontrola
U2: Wydanie: 06 | AG2: ZP | AH2: Obrywanie
U3: Strona 1 z 1 | AH3: ObrywKon
AH4: Mierzenie
A5: Nazwa firmy | B5: ZP | C5: ="*"&B5&"*" -> *ZP* | E5: Operacja | F5: Obrywanie | J5: ="*"&F5&"*" -> *Obrywanie* | X5: Data sprawdz | Z5: =TODAY() -> 46150 | AC5: ="*"&Z5-DATE(2013,5,1)&"*" -> *4755* | AH5: Pakowanie
AH6: Reklamacja
A7: Nr wewn. zlec. Prod | B7: Item | C7: Operator na kontroli | D7: Sprawdzono | E7: Ilość braków | AC7: Uwagi | AH7: Naprawa
F8: A | G8: B | H8: C | I8: D | J8: E | K8: F | L8: G | M8: H | N8: I | O8: J | P8: K | Q8: L | R8: M | S8: N | T8: O | U8: P | V8: R | W8: S | X8: T | Y8: U | Z8: V | AA8: W | AB8: X
B9: ='Braki_z kodami'!C9 -> 0 | C9: 030/P | D9: ='Braki_z kodami'!F9 -> 0 | E9: =SUM(F9:AB9) -> 0 | AF9: =CONCATENATE(IF(F9="","",F$8),F9) | AG9: =CONCATENATE(IF(G9="","",G$8),G9) | AH9: =CONCATENATE(IF(H9="","",H$8),H9) | AI9: =CONCATENATE(IF(I9="","",I$8),I9) | AJ9: =CONCATENATE(IF(J9="","",J$8),J9) | AK9: =CONCATENATE(IF(K9="","",K$8),K9) | AL9: =CONCATENATE(IF(L9="","",L$8),L9) | AM9: =CONCATENATE(IF(M9="","",M$8),M9) | AN9: =CONCATENATE(IF(S9="","",S$8),S9) | AO9: =CONCATENATE(IF(T9="","",T$8),T9) | AP9: =CONCATENATE(IF(U9="","",U$8),U9) | AQ9: =CONCATENATE(IF(V9="","",V$8),V9) | AR9: =CONCATENATE(IF(W9="","",W$8),W9) | AS9: =CONCATENATE(IF(X9="","",X$8),X9) | AT9: =CONCATENATE(IF(Y9="","",Y$8),Y9) | AU9: =CONCATENATE(IF(Z9="","",Z$8),Z9) | ... AW9: =CONCATENATE(IF(AB9="","",AB$8),AB9)
A10: =CONCATENATE("*",A9,"$",D9,AF9,AG9,AH9,AI9,AJ9,AK9,AL9,AM9,AN9,AO9,AP9,AQ9,AR9,AS9,AT9,AU9,AV9,AW9,"*") -> *$0*
B11: ='Braki_z kodami'!C11 -> 0 | C11: 030/P | D11: ='Braki_z kodami'!F11 -> 0 | E11: =SUM(F11:AB11) -> 0 | AF11: =CONCATENATE(IF(F11="","",F$8),F11) | AG11: =CONCATENATE(IF(G11="","",G$8),G11) | AH11: =CONCATENATE(IF(H11="","",H$8),H11) | AI11: =CONCATENATE(IF(I11="","",I$8),I11) | AJ11: =CONCATENATE(IF(J11="","",J$8),J11) | AK11: =CONCATENATE(IF(K11="","",K$8),K11) | AL11: =CONCATENATE(IF(L11="","",L$8),L11) | AM11: =CONCATENATE(IF(M11="","",M$8),M11) | AN11: =CONCATENATE(IF(S11="","",S$8),S11) | AO11: =CONCATENATE(IF(T11="","",T$8),T11) | AP11: =CONCATENATE(IF(U11="","",U$8),U11) | AQ11: =CONCATENATE(IF(V11="","",V$8),V11) | AR11: =CONCATENATE(IF(W11="","",W$8),W11) | AS11: =CONCATENATE(IF(X11="","",X$8),X11) | AT11: =CONCATENATE(IF(Y11="","",Y$8),Y11) | AU11: =CONCATENATE(IF(Z11="","",Z$8),Z11) | ... AW11: =CONCATENATE(IF(AB11="","",AB$8),AB11)
A12: =CONCATENATE("*",A11,"$",D11,AF11,AG11,AH11,AI11,AJ11,AK11,AL11,AM11,AN11,AO11,AP11,AQ11,AR11,AS11,AT11,AU11,AV11,AW11,"*") -> *$0*
B13: ='Braki_z kodami'!C13 -> 0 | C13: 030/P | D13: ='Braki_z kodami'!F13 -> 0 | E13: =SUM(F13:AB13) -> 0 | AF13: =CONCATENATE(IF(F13="","",F$8),F13) | AG13: =CONCATENATE(IF(G13="","",G$8),G13) | AH13: =CONCATENATE(IF(H13="","",H$8),H13) | AI13: =CONCATENATE(IF(I13="","",I$8),I13) | AJ13: =CONCATENATE(IF(J13="","",J$8),J13) | AK13: =CONCATENATE(IF(K13="","",K$8),K13) | AL13: =CONCATENATE(IF(L13="","",L$8),L13) | AM13: =CONCATENATE(IF(M13="","",M$8),M13) | AN13: =CONCATENATE(IF(S13="","",S$8),S13) | AO13: =CONCATENATE(IF(T13="","",T$8),T13) | AP13: =CONCATENATE(IF(U13="","",U$8),U13) | AQ13: =CONCATENATE(IF(V13="","",V$8),V13) | AR13: =CONCATENATE(IF(W13="","",W$8),W13) | AS13: =CONCATENATE(IF(X13="","",X$8),X13) | AT13: =CONCATENATE(IF(Y13="","",Y$8),Y13) | AU13: =CONCATENATE(IF(Z13="","",Z$8),Z13) | ... AW13: =CONCATENATE(IF(AB13="","",AB$8),AB13)
A14: =CONCATENATE("*",A13,"$",D13,AF13,AG13,AH13,AI13,AJ13,AK13,AL13,AM13,AN13,AO13,AP13,AQ13,AR13,AS13,AT13,AU13,AV13,AW13,"*") -> *$0*
B15: ='Braki_z kodami'!C15 -> 0 | C15: 030/P | D15: ='Braki_z kodami'!F15 -> 0 | E15: =SUM(F15:AB15) -> 0 | AF15: =CONCATENATE(IF(F15="","",F$8),F15) | AG15: =CONCATENATE(IF(G15="","",G$8),G15) | AH15: =CONCATENATE(IF(H15="","",H$8),H15) | AI15: =CONCATENATE(IF(I15="","",I$8),I15) | AJ15: =CONCATENATE(IF(J15="","",J$8),J15) | AK15: =CONCATENATE(IF(K15="","",K$8),K15) | AL15: =CONCATENATE(IF(L15="","",L$8),L15) | AM15: =CONCATENATE(IF(M15="","",M$8),M15) | AN15: =CONCATENATE(IF(S15="","",S$8),S15) | AO15: =CONCATENATE(IF(T15="","",T$8),T15) | AP15: =CONCATENATE(IF(U15="","",U$8),U15) | AQ15: =CONCATENATE(IF(V15="","",V$8),V15) | AR15: =CONCATENATE(IF(W15="","",W$8),W15) | AS15: =CONCATENATE(IF(X15="","",X$8),X15) | AT15: =CONCATENATE(IF(Y15="","",Y$8),Y15) | AU15: =CONCATENATE(IF(Z15="","",Z$8),Z15) | ... AW15: =CONCATENATE(IF(AB15="","",AB$8),AB15)
A16: =CONCATENATE("*",A15,"$",D15,AF15,AG15,AH15,AI15,AJ15,AK15,AL15,AM15,AN15,AO15,AP15,AQ15,AR15,AS15,AT15,AU15,AV15,AW15,"*") -> *$0*
B17: ='Braki_z kodami'!C17 -> 0 | C17: 030/P | D17: ='Braki_z kodami'!F17 -> 0 | E17: =SUM(F17:AB17) -> 0 | AC17: KZ | AF17: =CONCATENATE(IF(F17="","",F$8),F17) | AG17: =CONCATENATE(IF(G17="","",G$8),G17) | AH17: =CONCATENATE(IF(H17="","",H$8),H17) | AI17: =CONCATENATE(IF(I17="","",I$8),I17) | AJ17: =CONCATENATE(IF(J17="","",J$8),J17) | AK17: =CONCATENATE(IF(K17="","",K$8),K17) | AL17: =CONCATENATE(IF(L17="","",L$8),L17) | AM17: =CONCATENATE(IF(M17="","",M$8),M17) | AN17: =CONCATENATE(IF(S17="","",S$8),S17) | AO17: =CONCATENATE(IF(T17="","",T$8),T17) | AP17: =CONCATENATE(IF(U17="","",U$8),U17) | AQ17: =CONCATENATE(IF(V17="","",V$8),V17) | AR17: =CONCATENATE(IF(W17="","",W$8),W17) | AS17: =CONCATENATE(IF(X17="","",X$8),X17) | AT17: =CONCATENATE(IF(Y17="","",Y$8),Y17) | AU17: =CONCATENATE(IF(Z17="","",Z$8),Z17) | ... AW17: =CONCATENATE(IF(AB17="","",AB$8),AB17)
A18: =CONCATENATE("*",A17,"$",D17,AF17,AG17,AH17,AI17,AJ17,AK17,AL17,AM17,AN17,AO17,AP17,AQ17,AR17,AS17,AT17,AU17,AV17,AW17,"*") -> *$0*
B19: ='Braki_z kodami'!C19 -> 0 | C19: 030/P | D19: ='Braki_z kodami'!F19 -> 0 | E19: =SUM(F19:AB19) -> 0 | AF19: =CONCATENATE(IF(F19="","",F$8),F19) | AG19: =CONCATENATE(IF(G19="","",G$8),G19) | AH19: =CONCATENATE(IF(H19="","",H$8),H19) | AI19: =CONCATENATE(IF(I19="","",I$8),I19) | AJ19: =CONCATENATE(IF(J19="","",J$8),J19) | AK19: =CONCATENATE(IF(K19="","",K$8),K19) | AL19: =CONCATENATE(IF(L19="","",L$8),L19) | AM19: =CONCATENATE(IF(M19="","",M$8),M19) | AN19: =CONCATENATE(IF(S19="","",S$8),S19) | AO19: =CONCATENATE(IF(T19="","",T$8),T19) | AP19: =CONCATENATE(IF(U19="","",U$8),U19) | AQ19: =CONCATENATE(IF(V19="","",V$8),V19) | AR19: =CONCATENATE(IF(W19="","",W$8),W19) | AS19: =CONCATENATE(IF(X19="","",X$8),X19) | AT19: =CONCATENATE(IF(Y19="","",Y$8),Y19) | AU19: =CONCATENATE(IF(Z19="","",Z$8),Z19) | ... AW19: =CONCATENATE(IF(AB19="","",AB$8),AB19)
A20: =CONCATENATE("*",A19,"$",D19,AF19,AG19,AH19,AI19,AJ19,AK19,AL19,AM19,AN19,AO19,AP19,AQ19,AR19,AS19,AT19,AU19,AV19,AW19,"*") -> *$0*
B21: ='Braki_z kodami'!C21 -> 0 | C21: 030/P | D21: ='Braki_z kodami'!F21 -> 0 | E21: =SUM(F21:AB21) -> 0 | AF21: =CONCATENATE(IF(F21="","",F$8),F21) | AG21: =CONCATENATE(IF(G21="","",G$8),G21) | AH21: =CONCATENATE(IF(H21="","",H$8),H21) | AI21: =CONCATENATE(IF(I21="","",I$8),I21) | AJ21: =CONCATENATE(IF(J21="","",J$8),J21) | AK21: =CONCATENATE(IF(K21="","",K$8),K21) | AL21: =CONCATENATE(IF(L21="","",L$8),L21) | AM21: =CONCATENATE(IF(M21="","",M$8),M21) | AN21: =CONCATENATE(IF(S21="","",S$8),S21) | AO21: =CONCATENATE(IF(T21="","",T$8),T21) | AP21: =CONCATENATE(IF(U21="","",U$8),U21) | AQ21: =CONCATENATE(IF(V21="","",V$8),V21) | AR21: =CONCATENATE(IF(W21="","",W$8),W21) | AS21: =CONCATENATE(IF(X21="","",X$8),X21) | AT21: =CONCATENATE(IF(Y21="","",Y$8),Y21) | AU21: =CONCATENATE(IF(Z21="","",Z$8),Z21) | ... AW21: =CONCATENATE(IF(AB21="","",AB$8),AB21)
A22: =CONCATENATE("*",A21,"$",D21,AF21,AG21,AH21,AI21,AJ21,AK21,AL21,AM21,AN21,AO21,AP21,AQ21,AR21,AS21,AT21,AU21,AV21,AW21,"*") -> *$0*
B23: ='Braki_z kodami'!C23 -> 0 | C23: 030/P | D23: ='Braki_z kodami'!F23 -> 0 | E23: =SUM(F23:AB23) -> 0 | AC23: KZ | AF23: =CONCATENATE(IF(F23="","",F$8),F23) | AG23: =CONCATENATE(IF(G23="","",G$8),G23) | AH23: =CONCATENATE(IF(H23="","",H$8),H23) | AI23: =CONCATENATE(IF(I23="","",I$8),I23) | AJ23: =CONCATENATE(IF(J23="","",J$8),J23) | AK23: =CONCATENATE(IF(K23="","",K$8),K23) | AL23: =CONCATENATE(IF(L23="","",L$8),L23) | AM23: =CONCATENATE(IF(M23="","",M$8),M23) | AN23: =CONCATENATE(IF(S23="","",S$8),S23) | AO23: =CONCATENATE(IF(T23="","",T$8),T23) | AP23: =CONCATENATE(IF(U23="","",U$8),U23) | AQ23: =CONCATENATE(IF(V23="","",V$8),V23) | AR23: =CONCATENATE(IF(W23="","",W$8),W23) | AS23: =CONCATENATE(IF(X23="","",X$8),X23) | AT23: =CONCATENATE(IF(Y23="","",Y$8),Y23) | AU23: =CONCATENATE(IF(Z23="","",Z$8),Z23) | ... AW23: =CONCATENATE(IF(AB23="","",AB$8),AB23)
A24: =CONCATENATE("*",A23,"$",D23,AF23,AG23,AH23,AI23,AJ23,AK23,AL23,AM23,AN23,AO23,AP23,AQ23,AR23,AS23,AT23,AU23,AV23,AW23,"*") -> *$0*
B25: ='Braki_z kodami'!C25 -> 0 | C25: 030/P | D25: ='Braki_z kodami'!F25 -> 0 | E25: =SUM(F25:AB25) -> 0 | AF25: =CONCATENATE(IF(F25="","",F$8),F25) | AG25: =CONCATENATE(IF(G25="","",G$8),G25) | AH25: =CONCATENATE(IF(H25="","",H$8),H25) | AI25: =CONCATENATE(IF(I25="","",I$8),I25) | AJ25: =CONCATENATE(IF(J25="","",J$8),J25) | AL25: =CONCATENATE(IF(L25="","",L$8),L25) | AM25: =CONCATENATE(IF(M25="","",M$8),M25) | AN25: =CONCATENATE(IF(S25="","",S$8),S25) | AO25: =CONCATENATE(IF(T25="","",T$8),T25) | AP25: =CONCATENATE(IF(U25="","",U$8),U25) | AQ25: =CONCATENATE(IF(V25="","",V$8),V25) | AR25: =CONCATENATE(IF(W25="","",W$8),W25) | AS25: =CONCATENATE(IF(X25="","",X$8),X25) | AT25: =CONCATENATE(IF(Y25="","",Y$8),Y25) | AU25: =CONCATENATE(IF(Z25="","",Z$8),Z25) | ... AW25: =CONCATENATE(IF(AB25="","",AB$8),AB25)
A26: =CONCATENATE("*",A25,"$",D25,AF25,AG25,AH25,AI25,AJ25,AK25,AL25,AM25,AN25,AO25,AP25,AQ25,AR25,AS25,AT25,AU25,AV25,AW25,"*") -> *$0*
B27: ='Braki_z kodami'!C27 -> 0 | C27: 030/P | D27: ='Braki_z kodami'!F27 -> 0 | E27: =SUM(F27:AB27) -> 0 | AF27: =CONCATENATE(IF(F27="","",F$8),F27) | AG27: =CONCATENATE(IF(G27="","",G$8),G27) | AH27: =CONCATENATE(IF(H27="","",H$8),H27) | AI27: =CONCATENATE(IF(I27="","",I$8),I27) | AJ27: =CONCATENATE(IF(J27="","",J$8),J27) | AL27: =CONCATENATE(IF(L27="","",L$8),L27) | AM27: =CONCATENATE(IF(M27="","",M$8),M27) | AN27: =CONCATENATE(IF(S27="","",S$8),S27) | AO27: =CONCATENATE(IF(T27="","",T$8),T27) | AP27: =CONCATENATE(IF(U27="","",U$8),U27) | AQ27: =CONCATENATE(IF(V27="","",V$8),V27) | AR27: =CONCATENATE(IF(W27="","",W$8),W27) | AS27: =CONCATENATE(IF(X27="","",X$8),X27) | AT27: =CONCATENATE(IF(Y27="","",Y$8),Y27) | AU27: =CONCATENATE(IF(Z27="","",Z$8),Z27) | ... AW27: =CONCATENATE(IF(AB27="","",AB$8),AB27)
A28: =CONCATENATE("*",A27,"$",D27,AF27,AG27,AH27,AI27,AJ27,AK27,AL27,AM27,AN27,AO27,AP27,AQ27,AR27,AS27,AT27,AU27,AV27,AW27,"*") -> *$0*
B29: ='Braki_z kodami'!C29 -> 0 | C29: 030/P | D29: ='Braki_z kodami'!F29 -> 0 | E29: =SUM(F29:AB29) -> 0 | AF29: =CONCATENATE(IF(F29="","",F$8),F29) | AG29: =CONCATENATE(IF(G29="","",G$8),G29) | AH29: =CONCATENATE(IF(H29="","",H$8),H29) | AI29: =CONCATENATE(IF(I29="","",I$8),I29) | AJ29: =CONCATENATE(IF(J29="","",J$8),J29) | AK29: =CONCATENATE(IF(K29="","",K$8),K29) | AL29: =CONCATENATE(IF(L29="","",L$8),L29) | AM29: =CONCATENATE(IF(M29="","",M$8),M29) | AN29: =CONCATENATE(IF(S29="","",S$8),S29) | AO29: =CONCATENATE(IF(T29="","",T$8),T29) | AP29: =CONCATENATE(IF(U29="","",U$8),U29) | AQ29: =CONCATENATE(IF(V29="","",V$8),V29) | AR29: =CONCATENATE(IF(W29="","",W$8),W29) | AS29: =CONCATENATE(IF(X29="","",X$8),X29) | AT29: =CONCATENATE(IF(Y29="","",Y$8),Y29) | AU29: =CONCATENATE(IF(Z29="","",Z$8),Z29) | ... AW29: =CONCATENATE(IF(AB29="","",AB$8),AB29)
A30: =CONCATENATE("*",A29,"$",D29,AF29,AG29,AH29,AI29,AJ29,AK29,AL29,AM29,AN29,AO29,AP29,AQ29,AR29,AS29,AT29,AU29,AV29,AW29,"*") -> *$0*
B31: ='Braki_z kodami'!C31 -> 0 | C31: 030/P | D31: ='Braki_z kodami'!F31 -> 0 | E31: =SUM(F31:AB31) -> 0 | AF31: =CONCATENATE(IF(F31="","",F$8),F31) | AG31: =CONCATENATE(IF(G31="","",G$8),G31) | AH31: =CONCATENATE(IF(H31="","",H$8),H31) | AI31: =CONCATENATE(IF(I31="","",I$8),I31) | AJ31: =CONCATENATE(IF(J31="","",J$8),J31) | AN31: =CONCATENATE(IF(S31="","",S$8),S31) | AO31: =CONCATENATE(IF(T31="","",T$8),T31) | AP31: =CONCATENATE(IF(U31="","",U$8),U31) | AQ31: =CONCATENATE(IF(V31="","",V$8),V31) | AR31: =CONCATENATE(IF(W31="","",W$8),W31) | AS31: =CONCATENATE(IF(X31="","",X$8),X31) | AT31: =CONCATENATE(IF(Y31="","",Y$8),Y31) | AU31: =CONCATENATE(IF(Z31="","",Z$8),Z31) | ... AW31: =CONCATENATE(IF(AB31="","",AB$8),AB31)
A32: =CONCATENATE("*",A31,"$",D31,AF31,AG31,AH31,AI31,AJ31,AK31,AL31,AM31,AN31,AO31,AP31,AQ31,AR31,AS31,AT31,AU31,AV31,AW31,"*") -> *$0*
